Workbook

Sheet Bilanz
A1: ESWE Versorgungs AG, Wiesbaden
A2: Bilanz zum 31. Dezember
A3: HGB-Einzelabschluss – Gliederung gem. § 266 HGB i. V. m. § 265 Abs. 5 und 6 HGB
A4: Angaben in T€
A6: Position | B6: Anhang | C6: 31.12.2020 | D6: 31.12.2021 | E6: 31.12.2022 | F6: 31.12.2023 | G6: 31.12.2024
A8: AKTIVA
A9: A. Anlagevermögen | B9: (1)
A10: I. Immaterielle Vermögensgegenstände | C10: 829 | D10: 1044 | E10: 811 | F10: 658 | G10: 877
A11: II. Sachanlagen | C11: 159903 | D11: 174058 | E11: 189120 | F11: 197803 | G11: 209240
A12: III. Finanzanlagen | C12: 134084 | D12: 148234 | E12: 170186 | F12: 171960 | G12: 165190
A13: Anlagevermögen | C13: =SUM(C10:C12) -> 294816 | D13: =SUM(D10:D12) -> 323336 | E13: =SUM(E10:E12) -> 360117 | F13: =SUM(F10:F12) -> 370421 | G13: =SUM(G10:G12) -> 375307
A15: B. Umlaufvermögen
A16: I. Vorräte | B16: (2) | C16: 3898 | D16: 7162 | E16: 8158 | F16: 15439 | G16: 18356
A17: II. Forderungen und sonstige Vermögensgegenstände | B17: (3) | C17: 33013 | D17: 48391 | E17: 17853 | F17: 46747 | G17: 43316
A18: III. Kassenbestand und Guthaben bei Kreditinstituten | C18: 2987 | D18: 3616 | E18: 30611 | F18: 44992 | G18: 21543
A19: Umlaufvermögen | C19: =SUM(C16:C18) -> 39898 | D19: =SUM(D16:D18) -> 59169 | E19: =SUM(E16:E18) -> 56622 | F19: =SUM(F16:F18) -> 107178 | G19: =SUM(G16:G18) -> 83215
A21: C. Rechnungsabgrenzungsposten | C21: 2040 | D21: 2468 | E21: 3089 | F21: 3588 | G21: 581
A22: BILANZSUMME AKTIVA | C22: =C13+C19+C21 -> 336754 | D22: =D13+D19+D21 -> 384973 | E22: =E13+E19+E21 -> 419828 | F22: =F13+F19+F21 -> 481187 | G22: =G13+G19+G21 -> 459103
A25: PASSIVA
A26: A. Eigenkapital | B26: (4)
A27: I. Gezeichnetes Kapital | C27: 66013 | D27: 66013 | E27: 66013 | F27: 66013 | G27: 66013
A28: II. Kapitalrücklage | C28: 25426 | D28: 25426 | E28: 25426 | F28: 25426 | G28: 25426
A29: III. Gewinnrücklagen | C29: 25131 | D29: 25131 | E29: 25131 | F29: 35131 | G29: 35131
A30: IV. Bilanzgewinn | C30: 0 | D30: 0 | E30: 0 | F30: 0 | G30: 0
A31: Eigenkapital | C31: =SUM(C27:C30) -> 116570 | D31: =SUM(D27:D30) -> 116570 | E31: =SUM(E27:E30) -> 116570 | F31: =SUM(F27:F30) -> 126570 | G31: =SUM(G27:G30) -> 126570
A33: B. Empfangene Ertragszuschüsse | C33: 26940 | D33: 28577 | E33: 28900 | F33: 28009 | G33: 27685
A34: C. Rückstellungen | B34: (5) | C34: 80885 | D34: 95422 | E34: 90794 | F34: 111630 | G34: 91974
A35: D. Verbindlichkeiten | B35: (6) | C35: 112359 | D35: 144380 | E35: 183564 | F35: 214912 | G35: 212874
A36: E. Rechnungsabgrenzungsposten | C36: 0 | D36: 24 | E36: 0 | F36: 66 | G36: 0
A37: BILANZSUMME PASSIVA | C37: =C31+SUM(C33:C36) -> 336754 | D37: =D31+SUM(D33:D36) -> 384973 | E37: =E31+SUM(E33:E36) -> 419828 | F37: =F31+SUM(F33:F36) -> 481187 | G37: =G31+SUM(G33:G36) -> 459103
A39: Kontrolle: Bilanzsumme Aktiva ./. Passiva (muss 0 sein) | C39: =C22-C37 -> 0 | D39: =D22-D37 -> 0 | E39: =E22-E37 -> 0 | F39: =F22-F37 -> 0 | G39: =G22-G37 -> 0
A41: Quelle: Unternehmensregister – ESWE Versorgungs AG, Wiesbaden, HRB 2105.
A42: GJ 2020 und 2021: JA 2021, Seite 10 | GJ 2022: JA 2022, Seite 11–12 | GJ 2023: JA 2023, Seite 1–2 | GJ 2024: JA 2024, Seite 1–2.
A43: Blau = Eingabe direkt aus dem Jahresabschluss | Schwarz = Formel | Sämtliche Zwischen- und Endsummen sind Formeln.

Sheet GuV
A1: ESWE Versorgungs AG, Wiesbaden
A2: Gewinn- und Verlustrechnung
A3: Gesamtkostenverfahren gem. § 275 Abs. 2 HGB – für die Zeit vom 1. Januar bis 31. Dezember
A4: Angaben in T€
A6: Position | B6: Anhang | C6: 2020 | D6: 2021 | E6: 2022 | F6: 2023 | G6: 2024
A8: 1. Umsatzerlöse | B8: (10) | C8: 390642 | D8: 426532 | E8: 475683 | F8: 634062 | G8: 534653
A9: 2. Veränderung des Bestands an unfertigen Leistungen | C9: -175 | D9: -332 | E9: 860 | F9: 811 | G9: 69
A10: 3. Andere aktivierte Eigenleistungen | B10: (11) | C10: 2578 | D10: 3399 | E10: 3309 | F10: 1873 | G10: 2674
A11: 4. Sonstige betriebliche Erträge | B11: (12) | C11: 2546 | D11: 2486 | E11: 5989 | F11: 6383 | G11: 30279
A12: 5. Materialaufwand | B12: (13) | C12: 280935 | D12: 311386 | E12: 356302 | F12: 483927 | G12: 387160
A13: 6. Personalaufwand | B13: (14) | C13: 50102 | D13: 50803 | E13: 52128 | F13: 52026 | G13: 55317
A14: 7. Abschreibungen | B14: (15) | C14: 13344 | D14: 14180 | E14: 14545 | F14: 14570 | G14: 15673
A15: 8. Sonstige betriebliche Aufwendungen | B15: (16) | C15: 28985 | D15: 35338 | E15: 26581 | F15: 49684 | G15: 36261
A16: 9. Betriebliches Ergebnis | C16: =SUM(C8:C11)-SUM(C12:C15) -> 22225 | D16: =SUM(D8:D11)-SUM(D12:D15) -> 20378 | E16: =SUM(E8:E11)-SUM(E12:E15) -> 36285 | F16: =SUM(F8:F11)-SUM(F12:F15) -> 42922 | G16: =SUM(G8:G11)-SUM(G12:G15) -> 73264
A17: 10. Beteiligungsergebnis | B17: (17) | C17: 27606 | D17: 24466 | E17: 17558 | F17: 30534 | G17: 17765
A18: 11. Abschreibungen auf Finanzanlagen | B18: (18) | C18: 0 | D18: 0 | E18: 2037 | F18: 0 | G18: 8965
A19: 12. Zinsergebnis | B19: (19) | C19: -2064 | D19: -767 | E19: -49 | F19: 1281 | G19: 2218
A20: 13. ERGEBNIS VOR STEUERN | C20: =C16+C17-C18+C19 -> 47767 | D20: =D16+D17-D18+D19 -> 44077 | E20: =E16+E17-E18+E19 -> 51757 | F20: =F16+F17-F18+F19 -> 74737 | G20: =G16+G17-G18+G19 -> 84282
A21: 14. Steuern vom Einkommen und vom Ertrag | B21: (20) | C21: 3347 | D21: 3034 | E21: 3214 | F21: 3939 | G21: 5544
A22: 15. ERGEBNIS NACH STEUERN | C22: =C20-C21 -> 44420 | D22: =D20-D21 -> 41043 | E22: =E20-E21 -> 48543 | F22: =F20-F21 -> 70798 | G22: =G20-G21 -> 78738
A23: 16. Sonstige Steuern | B23: (21) | C23: 643 | D23: 300 | E23: 308 | F23: 237 | G23: 440
A24: 17. UNTERNEHMENSERGEBNIS / JAHRESÜBERSCHUSS | C24: =C22-C23 -> 43777 | D24: =D22-D23 -> 40743 | E24: =E22-E23 -> 48235 | F24: =F22-F23 -> 70561 | G24: =G22-G23 -> 78298
A25: 18. Einstellung in die anderen Gewinnrücklagen | B25: (22) | C25: 0 | D25: 0 | E25: 0 | F25: 10000 | G25: 0
A26: 19. Aufwendungen für Ausgleichszahlung | B26: (23) | C26: 17980 | D26: 16295 | E26: 17312 | F26: 21109 | G26: 29779
A27: 20. Aufgrund eines Ergebnisabführungsvertrags abgeführter Gewinn | B27: (24) | C27: 25797 | D27: 24448 | E27: 30923 | F27: 39452 | G27: 48519
A28: 21. BILANZGEWINN | C28: =C24-SUM(C25:C27) -> 0 | D28: =D24-SUM(D25:D27) -> 0 | E28: =E24-SUM(E25:E27) -> 0 | F28: =F24-SUM(F25:F27) -> 0 | G28: =G24-SUM(G25:G27) -> 0
A30: Kontrolle: Bilanzgewinn GuV ./. Bilanzgewinn Bilanz (muss 0 sein) | C30: =C28-Bilanz!C30 -> 0 | D30: =D28-Bilanz!D30 -> 0 | E30: =E28-Bilanz!E30 -> 0 | F30: =F28-Bilanz!F30 -> 0 | G30: =G28-Bilanz!G30 -> 0
A32: Quelle: Unternehmensregister – ESWE Versorgungs AG, Wiesbaden, HRB 2105.
A33: GJ 2020 und 2021: JA 2021, Seite 11 | GJ 2022: JA 2022, Seite 12–13 | GJ 2023: JA 2023, Seite 2 | GJ 2024: JA 2024, Seite 2.
A34: Hinweis GJ 2022: Der JA 2022 weist unter Pos. 16 „Sonstige Steuern“ 307 T€ aus. 48.543 ./. 307 = 48.236, ausgewiesen sind jedoch 48.235 T€.
A35: Der JA 2023 (Seite 23) nennt für 2022 308 T€, womit die Rechnung aufgeht. Angesetzt sind hier 308 T€.
A36: Hinweis GJ 2020/2021: Der JA 2021 kennt die Positionen „Abschreibungen auf Finanzanlagen“ und „Einstellung in die anderen Gewinnrücklagen“ nicht;
A37: sie sind mit 0 angesetzt, damit die Gliederung über alle fünf Jahre einheitlich ist. Die Nummerierung folgt dem JA 2024.

Sheet Kapitalflussrechnung
A1: ESWE Versorgungs AG, Wiesbaden
A2: Kapitalflussrechnung nach DRS 21
A3: Verkürzte Darstellung – die Gesellschaft veröffentlicht die Kapitalflussrechnung nur in dieser Form
A4: Angaben in Mio. €
A6: Position | B6: Anhang | C6: 2020 | D6: 2021 | E6: 2022 | F6: 2023 | G6: 2024
A8: Cashflow aus laufender Geschäftstätigkeit | C8: n. v. | D8: 49 | E8: 78 | F8: 47.3 | G8: 68.2
A9: Cashflow aus Investitionstätigkeit | C9: 1.7 | D9: -19.5 | E9: -34 | F9: 8.9 | G9: -5
A10: Cashflow aus Finanzierungstätigkeit | C10: -46.8 | D10: -28.9 | E10: -17 | F10: -41.8 | G10: -86.7
A11: Zahlungswirksame Veränderung des Finanzmittelfonds | C11: =IF(COUNT(C8:C10)=3,SUM(C8:C10),"n. v.") -> n. v. | D11: =IF(COUNT(D8:D10)=3,SUM(D8:D10),"n. v.") -> 0.6 | E11: =IF(COUNT(E8:E10)=3,SUM(E8:E10),"n. v.") -> 27 | F11: =IF(COUNT(F8:F10)=3,SUM(F8:F10),"n. v.") -> 14.4 | G11: =IF(COUNT(G8:G10)=3,SUM(G8:G10),"n. v.") -> -23.5
A13: Finanzmittelfonds am Anfang der Periode | C13: n. v. | D13: 3 | E13: 3.6 | F13: 30.6 | G13: 45
A14: Finanzmittelfonds am Ende der Periode | C14: =IF(AND(ISNUMBER(C13),ISNUMBER(C11)),C13+C11,"n. v.") -> n. v. | D14: =IF(AND(ISNUMBER(D13),ISNUMBER(D11)),D13+D11,"n. v.") -> 3.6 | E14: =IF(AND(ISNUMBER(E13),ISNUMBER(E11)),E13+E11,"n. v.") -> 30.6 | F14: =IF(AND(ISNUMBER(F13),ISNUMBER(F11)),F13+F11,"n. v.") -> 45 | G14: =IF(AND(ISNUMBER(G13),ISNUMBER(G11)),G13+G11,"n. v.") -> 21.5
A16: nachrichtlich: veröffentlichter Endbestand lt. Lagebericht | C16: 3 | D16: 3.6 | E16: 30.6 | F16: 45 | G16: 21.5
A17: Kontrolle: berechneter ./. veröffentlichter Endbestand (muss 0 sein) | C17: =IF(ISNUMBER(C14),ROUND(C14-C16,1),"n. v.") -> n. v. | D17: =IF(ISNUMBER(D14),ROUND(D14-D16,1),"n. v.") -> 0 | E17: =IF(ISNUMBER(E14),ROUND(E14-E16,1),"n. v.") -> 0 | F17: =IF(ISNUMBER(F14),ROUND(F14-F16,1),"n. v.") -> 0 | G17: =IF(ISNUMBER(G14),ROUND(G14-G16,1),"n. v.") -> 0
A18: Kontrolle: Endbestand ./. Kassenbestand lt. Bilanz (muss 0 sein) | C18: =IF(ISNUMBER(C14),ROUND(C14-Bilanz!C18/1000,1),"n. v.") -> n. v. | D18: =IF(ISNUMBER(D14),ROUND(D14-Bilanz!D18/1000,1),"n. v.") -> 0 | E18: =IF(ISNUMBER(E14),ROUND(E14-Bilanz!E18/1000,1),"n. v.") -> 0 | F18: =IF(ISNUMBER(F14),ROUND(F14-Bilanz!F18/1000,1),"n. v.") -> 0 | G18: =IF(ISNUMBER(G14),ROUND(G14-Bilanz!G18/1000,1),"n. v.") -> 0
A20: Quelle: Lagebericht im jeweiligen Jahresabschluss – JA 2023 Seite 25, JA 2024 Seite 26; GJ 2021 und 2022 aus dem Lageberichtstext.
A21: Eine Überleitung der einzelnen DRS-21-Posten (Jahresergebnis, Abschreibungen, Working-Capital-Veränderungen usw.) ist aus den
A22: veröffentlichten Abschlüssen nicht ableitbar – die Gesellschaft legt nur die drei Cashflow-Salden offen.
A23: GJ 2020: Der JA 2021 nennt als Vorjahreswerte nur Investitions- und Finanzierungscashflow; der laufende Cashflow ist nicht beziffert (n. v.).
A24: GJ 2022: Der JA 2022 nennt im Lagebericht 95,4 / -44,9 / -23,5 Mio. €, der JA 2023 für dasselbe Jahr 78,0 / -34,0 / -17,0 Mio. €.
A25: Die Summe (27,0 Mio. €) ist in beiden Fassungen identisch – es handelt sich um eine Umgliederung. Angesetzt sind die Werte des JA 2023.

Sheet Overview FS
A1: ESWE Versorgungs AG, Wiesbaden
A2: Overview Financial Statements 2020 – 2024
A3: Alle Werte sind Verweise (grün) auf die Blätter Bilanz, GuV und Kapitalflussrechnung – keine Doppelerfassung
A4: Angaben in T€, sofern nicht anders vermerkt
A6: Position | B6: Anhang | C6: 2020 | D6: 2021 | E6: 2022 | F6: 2023 | G6: 2024
A8: Ertragslage
A9: Umsatzerlöse | C9: =GuV!C8 -> 390642 | D9: =GuV!D8 -> 426532 | E9: =GuV!E8 -> 475683 | F9: =GuV!F8 -> 634062 | G9: =GuV!G8 -> 534653
A10: Materialaufwand | C10: =GuV!C12 -> 280935 | D10: =GuV!D12 -> 311386 | E10: =GuV!E12 -> 356302 | F10: =GuV!F12 -> 483927 | G10: =GuV!G12 -> 387160
A11: Personalaufwand | C11: =GuV!C13 -> 50102 | D11: =GuV!D13 -> 50803 | E11: =GuV!E13 -> 52128 | F11: =GuV!F13 -> 52026 | G11: =GuV!G13 -> 55317
A12: Abschreibungen | C12: =GuV!C14 -> 13344 | D12: =GuV!D14 -> 14180 | E12: =GuV!E14 -> 14545 | F12: =GuV!F14 -> 14570 | G12: =GuV!G14 -> 15673
A13: Sonstige betriebliche Aufwendungen | C13: =GuV!C15 -> 28985 | D13: =GuV!D15 -> 35338 | E13: =GuV!E15 -> 26581 | F13: =GuV!F15 -> 49684 | G13: =GuV!G15 -> 36261
A14: Betriebliches Ergebnis | C14: =GuV!C16 -> 22225 | D14: =GuV!D16 -> 20378 | E14: =GuV!E16 -> 36285 | F14: =GuV!F16 -> 42922 | G14: =GuV!G16 -> 73264
A15: Beteiligungsergebnis | C15: =GuV!C17 -> 27606 | D15: =GuV!D17 -> 24466 | E15: =GuV!E17 -> 17558 | F15: =GuV!F17 -> 30534 | G15: =GuV!G17 -> 17765
A16: Zinsergebnis | C16: =GuV!C19 -> -2064 | D16: =GuV!D19 -> -767 | E16: =GuV!E19 -> -49 | F16: =GuV!F19 -> 1281 | G16: =GuV!G19 -> 2218
A17: Ergebnis vor Steuern | C17: =GuV!C20 -> 47767 | D17: =GuV!D20 -> 44077 | E17: =GuV!E20 -> 51757 | F17: =GuV!F20 -> 74737 | G17: =GuV!G20 -> 84282
A18: Unternehmensergebnis / Jahresüberschuss | C18: =GuV!C24 -> 43777 | D18: =GuV!D24 -> 40743 | E18: =GuV!E24 -> 48235 | F18: =GuV!F24 -> 70561 | G18: =GuV!G24 -> 78298
A20: Vermögenslage
A21: Anlagevermögen | C21: =Bilanz!C13 -> 294816 | D21: =Bilanz!D13 -> 323336 | E21: =Bilanz!E13 -> 360117 | F21: =Bilanz!F13 -> 370421 | G21: =Bilanz!G13 -> 375307
A22: Umlaufvermögen | C22: =Bilanz!C19 -> 39898 | D22: =Bilanz!D19 -> 59169 | E22: =Bilanz!E19 -> 56622 | F22: =Bilanz!F19 -> 107178 | G22: =Bilanz!G19 -> 83215
A23: davon Kassenbestand und Guthaben bei Kreditinstituten | C23: =Bilanz!C18 -> 2987 | D23: =Bilanz!D18 -> 3616 | E23: =Bilanz!E18 -> 30611 | F23: =Bilanz!F18 -> 44992 | G23: =Bilanz!G18 -> 21543
A24: Rechnungsabgrenzungsposten | C24: =Bilanz!C21 -> 2040 | D24: =Bilanz!D21 -> 2468 | E24: =Bilanz!E21 -> 3089 | F24: =Bilanz!F21 -> 3588 | G24: =Bilanz!G21 -> 581
A25: Bilanzsumme | C25: =Bilanz!C22 -> 336754 | D25: =Bilanz!D22 -> 384973 | E25: =Bilanz!E22 -> 419828 | F25: =Bilanz!F22 -> 481187 | G25: =Bilanz!G22 -> 459103
A26: Eigenkapital | C26: =Bilanz!C31 -> 116570 | D26: =Bilanz!D31 -> 116570 | E26: =Bilanz!E31 -> 116570 | F26: =Bilanz!F31 -> 126570 | G26: =Bilanz!G31 -> 126570
A27: Empfangene Ertragszuschüsse | C27: =Bilanz!C33 -> 26940 | D27: =Bilanz!D33 -> 28577 | E27: =Bilanz!E33 -> 28900 | F27: =Bilanz!F33 -> 28009 | G27: =Bilanz!G33 -> 27685
A28: Rückstellungen | C28: =Bilanz!C34 -> 80885 | D28: =Bilanz!D34 -> 95422 | E28: =Bilanz!E34 -> 90794 | F28: =Bilanz!F34 -> 111630 | G28: =Bilanz!G34 -> 91974
A29: Verbindlichkeiten | C29: =Bilanz!C35 -> 112359 | D29: =Bilanz!D35 -> 144380 | E29: =Bilanz!E35 -> 183564 | F29: =Bilanz!F35 -> 214912 | G29: =Bilanz!G35 -> 212874
A31: Finanzlage (Mio. €)
A32: Cashflow aus laufender Geschäftstätigkeit | C32: =Kapitalflussrechnung!C8 -> n. v. | D32: =Kapitalflussrechnung!D8 -> 49 | E32: =Kapitalflussrechnung!E8 -> 78 | F32: =Kapitalflussrechnung!F8 -> 47.3 | G32: =Kapitalflussrechnung!G8 -> 68.2
A33: Cashflow aus Investitionstätigkeit | C33: =Kapitalflussrechnung!C9 -> 1.7 | D33: =Kapitalflussrechnung!D9 -> -19.5 | E33: =Kapitalflussrechnung!E9 -> -34 | F33: =Kapitalflussrechnung!F9 -> 8.9 | G33: =Kapitalflussrechnung!G9 -> -5
A34: Cashflow aus Finanzierungstätigkeit | C34: =Kapitalflussrechnung!C10 -> -46.8 | D34: =Kapitalflussrechnung!D10 -> -28.9 | E34: =Kapitalflussrechnung!E10 -> -17 | F34: =Kapitalflussrechnung!F10 -> -41.8 | G34: =Kapitalflussrechnung!G10 -> -86.7
A35: Veränderung des Finanzmittelfonds | C35: =Kapitalflussrechnung!C11 -> n. v. | D35: =Kapitalflussrechnung!D11 -> 0.6 | E35: =Kapitalflussrechnung!E11 -> 27 | F35: =Kapitalflussrechnung!F11 -> 14.4 | G35: =Kapitalflussrechnung!G11 -> -23.5
A36: Finanzmittelfonds am Ende der Periode | C36: =Kapitalflussrechnung!C14 -> n. v. | D36: =Kapitalflussrechnung!D14 -> 3.6 | E36: =Kapitalflussrechnung!E14 -> 30.6 | F36: =Kapitalflussrechnung!F14 -> 45 | G36: =Kapitalflussrechnung!G14 -> 21.5
A38: Kennzahlen
A39: Eigenkapitalquote | C39: =C26/C25 -> 0.34615773 | D39: =D26/D25 -> 0.30280046 | E39: =E26/E25 -> 0.27766133 | F39: =F26/F25 -> 0.26303703 | G39: =G26/G25 -> 0.27568977
A40: Anlagenintensität | C40: =C21/C25 -> 0.87546399 | D40: =D21/D25 -> 0.83989267 | E40: =E21/E25 -> 0.85777271 | F40: =F21/F25 -> 0.76980675 | G40: =G21/G25 -> 0.81747887
A41: Umsatzrendite (Unternehmensergebnis / Umsatz) | C41: =C18/C9 -> 0.11206424 | D41: =D18/D9 -> 0.095521555 | E41: =E18/E9 -> 0.10140156 | F41: =F18/F9 -> 0.11128407 | G41: =G18/G9 -> 0.14644639
A42: EBITDA (Betriebliches Ergebnis + Abschreibungen) | C42: =C14+C12 -> 35569 | D42: =D14+D12 -> 34558 | E42: =E14+E12 -> 50830 | F42: =F14+F12 -> 57492 | G42: =G14+G12 -> 88937
A43: nachrichtlich: Eigenkapitalquote lt. Lagebericht | C43: n. v. | D43: n. v. | E43: 0.278 | F43: 0.263 | G43: 0.276
A45: Kontrollen
A46: Bilanz: Aktiva ./. Passiva | C46: =Bilanz!C22-Bilanz!C37 -> 0 | D46: =Bilanz!D22-Bilanz!D37 -> 0 | E46: =Bilanz!E22-Bilanz!E37 -> 0 | F46: =Bilanz!F22-Bilanz!F37 -> 0 | G46: =Bilanz!G22-Bilanz!G37 -> 0
...

Sheet Quellen & Hinweise
A1: Quellen und Hinweise
A3: Gesellschaft | B3: ESWE Versorgungs AG, Wiesbaden – Amtsgericht Wiesbaden, HRB 2105
A4: Quelle | B4: Auszüge aus dem Unternehmensregister (offengelegte Jahres- und Tätigkeitsabschlüsse nach EnWG)
A6: JA 2021 | B6: GJ 01.01.–31.12.2021, Tag der Erstellung 13.02.2023 – liefert GJ 2021 und Vorjahr 2020
A7: JA 2022 | B7: GJ 01.01.–31.12.2022, Tag der Erstellung 29.02.2024 – liefert GJ 2022
A8: JA 2023 | B8: GJ 01.01.–31.12.2023, Tag der Erstellung 03.02.2025 – liefert GJ 2023
A9: JA 2024 | B9: GJ 01.01.–31.12.2024, Tag der Erstellung 16.01.2026 – liefert GJ 2024
A11: Abgrenzung | B11: Dargestellt ist ausschließlich der HGB-Einzelabschluss der ESWE Versorgungs AG.
B12: Die Tätigkeitsabschlüsse nach § 6b EnWG (Elektrizitätsverteilung, Gasverteilung, Messstellenbetrieb,
B13: öffentliche Infrastruktur) sind nicht Bestandteil dieser Auswertung.
B14: Ein Konzernabschluss wird nicht aufgestellt (§ 291 Abs. 1 HGB – Einbeziehung in den Konzernabschluss
B15: der WVV Wiesbaden Holding GmbH).
A17: Farbkonvention | B17: Blau = Eingabewert direkt aus dem Jahresabschluss | Schwarz = Formel im Blatt | Grün = Verweis auf anderes Blatt
B18: Sämtliche Zwischen- und Endsummen sind als Formeln hinterlegt und nirgends hartcodiert.
A20: Abweichung 1 | B20: JA 2022, Seite 12: Pos. 16 „Sonstige Steuern“ 2022 mit 307 T€ ausgewiesen. 48.543 ./. 307 = 48.236,
B21: ausgewiesen sind jedoch 48.235 T€. Der JA 2023, Seite 23, nennt für 2022 308 T€. Angesetzt: 308 T€.
A23: Abweichung 2 | B23: Kapitalflussrechnung 2022: JA 2022 nennt 95,4 / -44,9 / -23,5 Mio. €, JA 2023 für dasselbe Jahr
B24: 78,0 / -34,0 / -17,0 Mio. €. Die Summe (27,0 Mio. €) ist identisch – Umgliederung zwischen den
B25: Cashflow-Bereichen. Angesetzt sind die Werte des JA 2023.
A27: Abweichung 3 | B27: GJ 2020: Der laufende Cashflow wird im JA 2021 nur qualitativ beschrieben und nicht beziffert (n. v.).
A29: GuV-Gliederung | B29: Der JA 2021 kennt die Positionen „Abschreibungen auf Finanzanlagen“ und „Einstellung in die anderen
B30: Gewinnrücklagen“ nicht. Beide sind für 2020/2021 mit 0 angesetzt, damit die Gliederung über alle Jahre
B31: einheitlich ist. Die Positionsnummern folgen dem JA 2024.
A33: Vorlage evm AG | B33: Im Projektordner lagen nur die vier PDF-Auszüge – eine Excel-Vorlage der evm AG war nicht enthalten.
B34: Die Formatierung dieser Mappe orientiert sich daher an der Darstellung der Jahresabschlüsse selbst
B35: (Kopfzeile grau, Zebrastreifen, Summen mit Doppelstrich). Sobald die Vorlage vorliegt, lässt sich das Layout anpassen.
