Workbook
Name Stromverkauf: 'Overview FS'!$C$24:$E$24

Sheet Cover

Sheet Output>>

Sheet Overview
B2: EVM AG – Financial Overview 2020–2025
B3: EUR Mio. / % / x | C3: 2020 | D3: 2021 | E3: 2022 | F3: 2023 | G3: 2024 | H3: 2025
B5: Umsatz | C5: ='EVM KPIs'!C5 -> 699.60987 | D5: ='EVM KPIs'!D5 -> 845.45663 | E5: ='EVM KPIs'!E5 -> 1174.1012 | F5: ='EVM KPIs'!F5 -> 1362.5214 | G5: ='EVM KPIs'!G5 -> 1002.158 | H5: ='EVM KPIs'!H5 -> 999.2349
B6: Rohertrag | C6: ='EVM KPIs'!C7 -> 139.59621 | D6: ='EVM KPIs'!D7 -> 135.22188 | E6: ='EVM KPIs'!E7 -> 179.07642 | F6: ='EVM KPIs'!F7 -> 143.60181 | G6: ='EVM KPIs'!G7 -> 185.02263 | H6: ='EVM KPIs'!H7 -> 179.46957
B7: Rohertragsmarge | C7: ='EVM KPIs'!C9 -> 0.19918422 | D7: ='EVM KPIs'!D9 -> 0.16008132 | E7: ='EVM KPIs'!E9 -> 0.15250945 | F7: ='EVM KPIs'!F9 -> 0.10539829 | G7: ='EVM KPIs'!G9 -> 0.18453934 | H7: ='EVM KPIs'!H9 -> 0.17963681
B8: EBITDA | C8: ='EVM KPIs'!C10 -> 86.713073 | D8: ='EVM KPIs'!D10 -> 79.702945 | E8: ='EVM KPIs'!E10 -> 98.454373 | F8: ='EVM KPIs'!F10 -> 71.546576 | G8: ='EVM KPIs'!G10 -> 90.376031 | H8: ='EVM KPIs'!H10 -> 91.324092
B9: Net Debt | C9: ='EVM KPIs'!C24 -> 173.81036 | D9: ='EVM KPIs'!D24 -> 249.15106 | E9: ='EVM KPIs'!E24 -> 169.00466 | F9: ='EVM KPIs'!F24 -> 196.43201 | G9: ='EVM KPIs'!G24 -> 203.43755 | H9: ='EVM KPIs'!H24 -> 237.23102
B10: Net Debt / EBITDA | C10: ='EVM KPIs'!C26 -> 2.0044309 | D10: ='EVM KPIs'!D26 -> 3.1259957 | E10: ='EVM KPIs'!E26 -> 1.7165785 | F10: ='EVM KPIs'!F26 -> 2.7455123 | G10: ='EVM KPIs'!G26 -> 2.2510123 | H10: ='EVM KPIs'!H26 -> 2.5976827
B11: Capex | C11: ='EVM KPIs'!C27 -> 29.944 | D11: ='EVM KPIs'!D27 -> 29.104 | E11: ='EVM KPIs'!E27 -> 22.865 | F11: ='EVM KPIs'!F27 -> 27.728 | G11: ='EVM KPIs'!G27 -> 24.02 | H11: ='EVM KPIs'!H27 -> 43.148
B12: OCF | C12: ='EVM KPIs'!C13 -> 64.502 | D12: ='EVM KPIs'!D13 -> 19.969 | E12: ='EVM KPIs'!E13 -> 200.708 | F12: ='EVM KPIs'!F13 -> -18.566 | G12: ='EVM KPIs'!G13 -> 60.789 | H12: ='EVM KPIs'!H13 -> 48.858
B13: ICF | C13: ='EVM KPIs'!C14 -> -6.681 | D13: ='EVM KPIs'!D14 -> -25.314 | E13: ='EVM KPIs'!E14 -> -14.953 | F13: ='EVM KPIs'!F14 -> -5.502 | G13: ='EVM KPIs'!G14 -> -5.878 | H13: ='EVM KPIs'!H14 -> -41.741
B14: FCF | C14: ='EVM Cashflow'!C7 -> -47.081 | D14: ='EVM Cashflow'!D7 -> -47.209 | E14: ='EVM Cashflow'!E7 -> -27.507 | F14: ='EVM Cashflow'!F7 -> -37.799 | G14: ='EVM Cashflow'!G7 -> -49.018 | H14: ='EVM Cashflow'!H7 -> -48.175
B15: Total CF | C15: =SUM(C12:C14) -> 10.74 | D15: =SUM(D12:D14) -> -52.554 | E15: =SUM(E12:E14) -> 158.248 | F15: =SUM(F12:F14) -> -61.867 | G15: =SUM(G12:G14) -> 5.893 | H15: =SUM(H12:H14) -> -41.058
B17: FFCF | C17: ='EVM KPIs'!C16 -> 57.821 | D17: ='EVM KPIs'!D16 -> -5.345 | E17: ='EVM KPIs'!E16 -> 185.755 | F17: ='EVM KPIs'!F16 -> -24.068 | G17: ='EVM KPIs'!G16 -> 54.911 | H17: ='EVM KPIs'!H16 -> 7.117
B19: Kassenbestand | C19: ='EVM KPIs'!C19 -> 25.827598 | D19: ='EVM KPIs'!D19 -> 1.29242 | E19: ='EVM KPIs'!E19 -> 131.52222 | F19: ='EVM KPIs'!F19 -> 69.654726 | G19: ='EVM KPIs'!G19 -> 75.547681 | H19: ='EVM KPIs'!H19 -> 34.489319
B20: Eigenkapitalquote | C20: ='EVM KPIs'!C18 -> 0.42103781 | D20: ='EVM KPIs'!D18 -> 0.37335501 | E20: ='EVM KPIs'!E18 -> 0.35337425 | F20: ='EVM KPIs'!F18 -> 0.36848118 | G20: ='EVM KPIs'!G18 -> 0.37457217 | H20: ='EVM KPIs'!H18 -> 0.39108362
B23: Umsatzaufteilung
B25: Erdgasverkauf | C25: ='EVM Capex Revenue'!C14 -> 239.596 | D25: ='EVM Capex Revenue'!D14 -> 339.065 | E25: ='EVM Capex Revenue'!E14 -> 521.168 | F25: ='EVM Capex Revenue'!F14 -> 584.98 | G25: ='EVM Capex Revenue'!G14 -> 406.216 | H25: ='EVM Capex Revenue'!H14 -> 410.833
B26: Stromverkauf | C26: ='EVM Capex Revenue'!C15 -> 361.501 | D26: ='EVM Capex Revenue'!D15 -> 411.896 | E26: ='EVM Capex Revenue'!E15 -> 543.905 | F26: ='EVM Capex Revenue'!F15 -> 670.137 | G26: ='EVM Capex Revenue'!G15 -> 489.079 | H26: ='EVM Capex Revenue'!H15 -> 479.689
B27: Miet- und Pachterträge | C27: ='EVM Capex Revenue'!C16 -> 45.664 | D27: ='EVM Capex Revenue'!D16 -> 35.188 | E27: ='EVM Capex Revenue'!E16 -> 36.094 | F27: ='EVM Capex Revenue'!F16 -> 34.804 | G27: ='EVM Capex Revenue'!G16 -> 35.548 | H27: ='EVM Capex Revenue'!H16 -> 37.341
B28: Dienstleistungserträge | C28: ='EVM Capex Revenue'!C17 -> 23.325 | D28: ='EVM Capex Revenue'!D17 -> 23.17 | E28: ='EVM Capex Revenue'!E17 -> 23.124 | F28: ='EVM Capex Revenue'!F17 -> 24.799 | G28: ='EVM Capex Revenue'!G17 -> 28.192 | H28: ='EVM Capex Revenue'!H17 -> 28.926
B29: Sonstige | C29: ='EVM Capex Revenue'!C18 -> 29.524 | D29: ='EVM Capex Revenue'!D18 -> 36.138 | E29: ='EVM Capex Revenue'!E18 -> 49.81 | F29: ='EVM Capex Revenue'!F18 -> 47.801 | G29: ='EVM Capex Revenue'!G18 -> 43.123 | H29: ='EVM Capex Revenue'!H18 -> 42.446
B32: enm – ergänzende operative Finanzkennzahlen
B33: EUR Mio. / % | C33: 2020 | D33: 2021 | E33: 2022 | F33: 2023 | G33: 2024 | H33: 2025
B35: Umsatz | C35: ='ENM KPIs'!B4 -> 311.44739 | D35: ='ENM KPIs'!C4 -> 313.00273 | E35: ='ENM KPIs'!D4 -> 340.52224 | F35: ='ENM KPIs'!E4 -> 407.47916 | G35: ='ENM KPIs'!F4 -> 379.54604 | H35: ='ENM KPIs'!G4 -> 0
B36: EBITDA | C36: ='ENM KPIs'!B8 -> -4.4076399 | D36: ='ENM KPIs'!C8 -> 9.3809481 | E36: ='ENM KPIs'!D8 -> -2.3540333 | F36: ='ENM KPIs'!E8 -> 16.570261 | G36: ='ENM KPIs'!F8 -> 18.719315 | H36: ='ENM KPIs'!G8 -> 0
B37: Capex | C37: ='ENM KPIs'!B14 -> 1.379 | D37: ='ENM KPIs'!C14 -> 13.01 | E37: ='ENM KPIs'!D14 -> 13.193 | F37: ='ENM KPIs'!E14 -> 16.373 | G37: ='ENM KPIs'!F14 -> 24.156 | H37: ='ENM KPIs'!G14 -> 0
B38: OCF | C38: ='ENM KPIs'!B10 -> 14.398 | D38: ='ENM KPIs'!C10 -> 0.131 | E38: ='ENM KPIs'!D10 -> -9.54 | F38: ='ENM KPIs'!E10 -> 4.544 | G38: ='ENM KPIs'!F10 -> 14.406 | H38: ='ENM KPIs'!G10 -> 0
B39: FCF | C39: ='ENM KPIs'!B12 -> 12.367 | D39: ='ENM KPIs'!C12 -> -9.172 | E39: ='ENM KPIs'!D12 -> -18.547 | F39: ='ENM KPIs'!E12 -> -6.461 | G39: ='ENM KPIs'!F12 -> -2.955 | H39: ='ENM KPIs'!G12 -> 0
B40: Eigenkapitalquote | C40: ='ENM KPIs'!B13 -> 0 | D40: ='ENM KPIs'!C13 -> 0.6407616 | E40: ='ENM KPIs'!D13 -> 0.60320631 | F40: ='ENM KPIs'!E13 -> 0.59169257 | G40: ='ENM KPIs'!F13 -> 0.5407293 | H40: ='ENM KPIs'!G13 -> 0
B43: Methodik: Net Debt = Verbindlichkeiten gegenüber Kreditinstituten abzüglich Kassenbestand. Intercompany-Finanzierungen und Pensionsrückstellungen sind nicht einbezogen, da eine belastbare Trennung von operativen und finanzierungsbezogenen Positionen aus den veröffentlichten Einzelabschlüssen nicht durchgängig möglich ist. FCF = OCF + ICF.
B46: Die GuV-Reihen von evm AG und enm folgen nun einer einheitlichen Maximalstruktur: Sämtliche Positionen, die in mindestens einem Abschluss 2020–2024 separat ausgewiesen wurden, sind enthalten. Nicht separat ausgewiesene Positionen werden als „n.a.“ dargestellt und nicht als null interpretiert.

Sheet Overview FS
B2: EVM AG – Financial Overview 2021–2025
B3: EUR Mio. / % / x | C3: 2021 | D3: 2022 | E3: 2023 | F3: 2024 | G3: 2025
B4: Umsatz | C4: ='EVM KPIs'!D5 -> 845.45663 | D4: ='EVM KPIs'!E5 -> 1174.1012 | E4: ='EVM KPIs'!F5 -> 1362.5214 | F4: ='EVM KPIs'!G5 -> 1002.158 | G4: ='EVM KPIs'!H5 -> 999.2349
B5: Rohertrag | C5: ='EVM KPIs'!D7 -> 135.22188 | D5: ='EVM KPIs'!E7 -> 179.07642 | E5: ='EVM KPIs'!F7 -> 143.60181 | F5: ='EVM KPIs'!G7 -> 185.02263 | G5: ='EVM KPIs'!H7 -> 179.46957
B6: Rohertragsmarge | C6: ='EVM KPIs'!D9 -> 0.16008132 | D6: ='EVM KPIs'!E9 -> 0.15250945 | E6: ='EVM KPIs'!F9 -> 0.10539829 | F6: ='EVM KPIs'!G9 -> 0.18453934 | G6: ='EVM KPIs'!H9 -> 0.17963681
B7: EBITDA | C7: ='EVM KPIs'!D10 -> 79.702945 | D7: ='EVM KPIs'!E10 -> 98.454373 | E7: ='EVM KPIs'!F10 -> 71.546576 | F7: ='EVM KPIs'!G10 -> 90.376031 | G7: ='EVM KPIs'!H10 -> 91.324092
B8: Capex | C8: ='EVM KPIs'!D27 -> 29.104 | D8: ='EVM KPIs'!E27 -> 22.865 | E8: ='EVM KPIs'!F27 -> 27.728 | F8: ='EVM KPIs'!G27 -> 24.02 | G8: ='EVM KPIs'!H27 -> 43.148
C10: 2021 | D10: 2022 | E10: 2023 | F10: 2024 | G10: 2025
B11: Operating Cash Flow | C11: ='EVM KPIs'!D13 -> 19.969 | D11: ='EVM KPIs'!E13 -> 200.708 | E11: ='EVM KPIs'!F13 -> -18.566 | F11: ='EVM KPIs'!G13 -> 60.789 | G11: ='EVM KPIs'!H13 -> 48.858
B12: Investing Cash Flow | C12: ='EVM KPIs'!D14 -> -25.314 | D12: ='EVM KPIs'!E14 -> -14.953 | E12: ='EVM KPIs'!F14 -> -5.502 | F12: ='EVM KPIs'!G14 -> -5.878 | G12: ='EVM KPIs'!H14 -> -41.741
B13: Financing Cashflow | C13: =Overview!D14 -> -47.209 | D13: =Overview!E14 -> -27.507 | E13: =Overview!F14 -> -37.799 | F13: =Overview!G14 -> -49.018 | G13: =Overview!H14 -> -48.175
B14: CF | C14: =SUM(C11:C13) -> -52.554 | D14: =SUM(D11:D13) -> 158.248 | E14: =SUM(E11:E13) -> -61.867 | F14: =SUM(F11:F13) -> 5.893 | G14: =SUM(G11:G13) -> -41.058
C16: 2021 | D16: 2022 | E16: 2023 | F16: 2024 | G16: 2025
B17: Kassenbestand | C17: ='EVM KPIs'!D19 -> 1.29242 | D17: ='EVM KPIs'!E19 -> 131.52222 | E17: ='EVM KPIs'!F19 -> 69.654726 | F17: ='EVM KPIs'!G19 -> 75.547681 | G17: ='EVM KPIs'!H19 -> 34.489319
B18: Net Debt | C18: ='EVM KPIs'!D24 -> 249.15106 | D18: ='EVM KPIs'!E24 -> 169.00466 | E18: ='EVM KPIs'!F24 -> 196.43201 | F18: ='EVM KPIs'!G24 -> 203.43755 | G18: ='EVM KPIs'!H24 -> 237.23102
B19: Eigenkapitalquote | C19: ='EVM KPIs'!D18 -> 0.37335501 | D19: ='EVM KPIs'!E18 -> 0.35337425 | E19: ='EVM KPIs'!F18 -> 0.36848118 | F19: ='EVM KPIs'!G18 -> 0.37457217 | G19: ='EVM KPIs'!H18 -> 0.39108362
B22: Umsatzaufteilung
B23: Stromverkauf | C23: =G23/$G$4 -> 0.48005629 | G23: ='EVM Capex Revenue'!H15 -> 479.689
B24: Erdgasverkauf | C24: =G24/$G$4 -> 0.41114757 | G24: ='EVM Capex Revenue'!H14 -> 410.833
B25: Miet- und Pachterträge | C25: =G25/$G$4 -> 0.037369591 | G25: ='EVM Capex Revenue'!H16 -> 37.341
B26: Dienstleistungserträge | C26: =G26/$G$4 -> 0.028948148 | G26: ='EVM Capex Revenue'!H17 -> 28.926
B27: Sonstige | C27: =G27/$G$4 -> 0.0424785 | G27: ='EVM Capex Revenue'!H18 -> 42.446
B30: enm – ergänzende operative Finanzkennzahlen
B31: EUR Mio. / % | C31: 2020 | D31: 2021 | E31: 2022 | F31: 2023 | G31: 2024
B32: Umsatz | C32: ='ENM KPIs'!B4 -> 311.44739 | D32: ='ENM KPIs'!C4 -> 313.00273 | E32: ='ENM KPIs'!D4 -> 340.52224 | F32: ='ENM KPIs'!E4 -> 407.47916 | G32: ='ENM KPIs'!F4 -> 379.54604
B33: EBITDA | C33: ='ENM KPIs'!B8 -> -4.4076399 | D33: ='ENM KPIs'!C8 -> 9.3809481 | E33: ='ENM KPIs'!D8 -> -2.3540333 | F33: ='ENM KPIs'!E8 -> 16.570261 | G33: ='ENM KPIs'!F8 -> 18.719315
B34: Capex | C34: ='ENM KPIs'!B14 -> 1.379 | D34: ='ENM KPIs'!C14 -> 13.01 | E34: ='ENM KPIs'!D14 -> 13.193 | F34: ='ENM KPIs'!E14 -> 16.373 | G34: ='ENM KPIs'!F14 -> 24.156
B35: OCF | C35: ='ENM KPIs'!B10 -> 14.398 | D35: ='ENM KPIs'!C10 -> 0.131 | E35: ='ENM KPIs'!D10 -> -9.54 | F35: ='ENM KPIs'!E10 -> 4.544 | G35: ='ENM KPIs'!F10 -> 14.406
B36: FCF | C36: ='ENM KPIs'!B12 -> 12.367 | D36: ='ENM KPIs'!C12 -> -9.172 | E36: ='ENM KPIs'!D12 -> -18.547 | F36: ='ENM KPIs'!E12 -> -6.461 | G36: ='ENM KPIs'!F12 -> -2.955
B37: Eigenkapitalquote | C37: ='ENM KPIs'!B13 -> 0 | D37: ='ENM KPIs'!C13 -> 0.6407616 | E37: ='ENM KPIs'!D13 -> 0.60320631 | F37: ='ENM KPIs'!E13 -> 0.59169257 | G37: ='ENM KPIs'!F13 -> 0.5407293
B40: Entwicklung der Verschuldung
C41: 2021 | D41: 2022 | E41: 2023 | F41: 2024 | G41: 2025
B42: Net Debt | C42: ='EVM KPIs'!D24 -> 249.15106 | D42: ='EVM KPIs'!E24 -> 169.00466 | E42: ='EVM KPIs'!F24 -> 196.43201 | F42: ='EVM KPIs'!G24 -> 203.43755 | G42: ='EVM KPIs'!H24 -> 237.23102
B43: Net Debt / EBITDA | C43: ='EVM KPIs'!D26 -> 3.1259957 | D43: ='EVM KPIs'!E26 -> 1.7165785 | E43: ='EVM KPIs'!F26 -> 2.7455123 | F43: ='EVM KPIs'!G26 -> 2.2510123 | G43: ='EVM KPIs'!H26 -> 2.5976827
B46: Methodik: Net Debt = Verbindlichkeiten gegenüber Kreditinstituten abzüglich Kassenbestand. Intercompany-Finanzierungen und Pensionsrückstellungen sind nicht einbezogen, da eine belastbare Trennung von operativen und finanzierungsbezogenen Positionen aus den veröffentlichten Einzelabschlüssen nicht durchgängig möglich ist. FCF = OCF + ICF.
B49: Die GuV-Reihen von evm AG und enm folgen nun einer einheitlichen Maximalstruktur: Sämtliche Positionen, die in mindestens einem Abschluss 2020–2025 separat ausgewiesen wurden, sind enthalten. Nicht separat ausgewiesene Positionen werden als „n.a.“ dargestellt und nicht als null interpretiert.

Sheet Input>>

Sheet EVM Bilanz
B2: Energieversorgung Mittelrhein AG – Bilanz 2020–2025
B3: EUR Mio. | C3: 2020 | D3: =C3+1 -> 2021 | E3: =D3+1 -> 2022 | F3: =E3+1 -> 2023 | G3: =F3+1 -> 2024 | H3: =G3+1 -> 2025
B5: A. Anlagevermögen | C5: =C6+C10+C15 -> 464.88531 | D5: =D6+D10+D15 -> 492.12125 | E5: =E6+E10+E15 -> 492.16858 | F5: =F6+F10+F15 -> 490.74289 | G5: =G6+G10+G15 -> 498.92701 | H5: =H6+H10+H15 -> 526.79159
B6: I. Immaterielle Vermögensgegenstände | C6: =C7+C8+C9 -> 2.894685 | D6: =D7+D8+D9 -> 2.4441156 | E6: =E7+E8+E9 -> 1.9450065 | F6: =F7+F8+F9 -> 1.5032547 | G6: =G7+G8+G9 -> 1.9420803 | H6: =H7+H8+H9 -> 1.7202426
B7: 1. entgeltlich erworbene Konzessionen, gewerbliche Schutzrechte und ähnliche Rechte und Werte sowie Lizenzen an solchen Rechten und Werten | C7: 2.2845248 | D7: 1.8847364 | E7: 1.4202901 | F7: 1.0309312 | G7: 1.5221496 | H7: 1.3527047
B8: 2. Geschäfts- oder Firmenwert | C8: 0.59905227 | D8: 0.54913124 | E8: 0.5153284 | F8: 0.46379556 | G8: 0.41226272 | H8: 0.36072988
B9: 3. Baukostenzuschüsse | C9: 0.011108 | D9: 0.010248 | E9: 0.009388 | F9: 0.008528 | G9: 0.007668 | H9: 0.006808
B10: II. Sachanlagen | C10: =C11+C12+C13+C14 -> 144.7206 | D10: =D11+D12+D13+D14 -> 160.56205 | E10: =E11+E12+E13+E14 -> 168.3751 | F10: =F11+F12+F13+F14 -> 171.00285 | G10: =G11+G12+G13+G14 -> 178.7261 | H10: =H11+H12+H13+H14 -> 204.39331
B11: 1. Grundstücke, grundstücksgleiche Rechte und Bauten einschließlich der Bauten auf fremden Grundstücken | C11: 11.262106 | D11: 10.131873 | E11: 9.0328036 | F11: 8.5585716 | G11: 8.0819163 | H11: 7.656954
B12: 2. technische Anlagen und Maschinen | C12: 128.31186 | D12: 141.44172 | E12: 151.99207 | F12: 151.39464 | G12: 159.72651 | H12: 183.19935
B13: 3. Betriebs- und Geschäftsausstattung | C13: 1.8509121 | D13: 2.059932 | E13: 1.8317892 | F13: 1.8879635 | G13: 1.730196 | H13: 1.7179131
B14: 4. Anlagen im Bau | C14: 3.2957272 | D14: 6.9285319 | E14: 5.5184387 | F14: 9.161676 | G14: 9.187484 | H14: 11.819098
B15: III. Finanzanlagen | C15: =C16+C17+C18+C19+C20+C21 -> 317.27002 | D15: =D16+D17+D18+D19+D20+D21 -> 329.11508 | E15: =E16+E17+E18+E19+E20+E21 -> 321.84848 | F15: =F16+F17+F18+F19+F20+F21 -> 318.23678 | G15: =G16+G17+G18+G19+G20+G21 -> 318.25883 | H15: =H16+H17+H18+H19+H20+H21 -> 320.67804
B16: 1. Anteile an verbundenen Unternehmen | C16: 225.25099 | D16: 239.25099 | E16: 242.65594 | F16: 242.26355 | G16: 242.2758 | H16: 242.2758
B17: 2. Ausleihungen an verbundene Unternehmen | C17: 25.1921 | D17: 22.968566 | E17: 12.118566 | F17: 9.1211659 | G17: 7.1211659 | H17: 4.8761659
B18: 3. Beteiligungen | C18: 14.218145 | D18: 14.218145 | E18: 14.268145 | F18: 14.115918 | G18: 13.993911 | H18: 14.018911
B19: 4. Ausleihungen an Unternehmen, mit denen ein Beteiligungsverhältnis besteht | C19: 1.7548681 | D19: 1.8475121 | E19: 1.9899328 | F19: 1.9321237 | G19: 4.0740776 | H19: 8.7157873
B20: 5. Wertpapiere des Anlagevermögens 50.783.225,56 | C20: 50.783226 | D20: 50.783226 | E20: 50.783226 | F20: 50.783226 | G20: 50.783226 | H20: 50.783226
B21: 6. sonstige Ausleihungen | C21: 0.0706863 | D21: 0.04664205 | E21: 0.03267556 | F21: 0.02079718 | G21: 0.01064949 | H21: 0.00814809
B22: B. Umlaufvermögen | C22: =C23+C27+C31 -> 128.33156 | D22: =D23+D27+D31 -> 185.44423 | E22: =E23+E27+E31 -> 244.27364 | F22: =F23+F27+F31 -> 235.13547 | G22: =G23+G27+G31 -> 252.33127 | H22: =H23+H27+H31 -> 210.57915
B23: I. Vorräte | C23: =C24+C25+C26 -> 1.229864 | D23: =D24+D25+D26 -> 26.230683 | E23: =E24+E25+E26 -> 0.87750041 | F23: =F24+F25+F26 -> 24.685277 | G23: =G24+G25+G26 -> 32.602191 | H23: =H24+H25+H26 -> 41.186683
B24: 1. nEHS-Zertifikate | D24: 25.75 | F24: 24.00392 | G24: 31.50343 | H24: 40.153577
B25: 2. unfertige Leistungen | C25: 1.229864 | D25: 0.48068327 | E25: 0.5782933 | F25: 0.52495698 | G25: 0.98581789 | H25: 0.81992623
B26: 3. fertige Erzeugnisse und Waren | E26: 0.29920711 | F26: 0.15640037 | G26: 0.11294346 | H26: 0.21317984
B27: II. Forderungen und sonstige Vermögensgegenstände | C27: =C28+C29+C30 -> 101.2741 | D27: =D28+D29+D30 -> 157.92112 | E27: =E28+E29+E30 -> 111.87392 | F27: =F28+F29+F30 -> 140.79546 | G27: =G28+G29+G30 -> 144.1814 | H27: =H28+H29+H30 -> 134.90314
B28: 1. Forderungen aus Lieferungen und Leistungen | C28: 76.539947 | D28: 138.02013 | E28: 83.1553 | F28: 114.71624 | G28: 118.74064 | H28: 116.03586
B29: 2. Forderungen gegen nahe stehende Unternehmen | C29: 19.284357 | D29: 12.217939 | E29: 11.114513 | F29: 16.167013 | G29: 15.61088 | H29: 13.194713
B30: 3. sonstige Vermögensgegenstände | C30: 5.4497976 | D30: 7.683058 | E30: 17.604104 | F30: 9.9122139 | G30: 9.8298799 | H30: 5.6725733
B31: III. Kassenbestand, Bundesbankguthaben, Guthaben bei Kreditinstituten und Schecks | C31: 25.827598 | D31: 1.29242 | E31: 131.52222 | F31: 69.654726 | G31: 75.547681 | H31: 34.489319
B32: C. Rechnungsabgrenzungsposten | C32: 0.8383464 | D32: 0.4106193 | E32: 0.5690655 | F32: 0.88367328 | G32: 0.64073185 | H32: 2.0608528
B33: Aktiva | C33: =C5+C22+C32 -> 594.05522 | D33: =D5+D22+D32 -> 677.9761 | E33: =E5+E22+E32 -> 737.01129 | F33: =F5+F22+F32 -> 726.76203 | G33: =G5+G22+G32 -> 751.89901 | H33: =H5+H22+H32 -> 739.43159
B35: A. Eigenkapital | C35: =C36+C37+C38+C41 -> 250.11971 | D35: =D36+D37+D38+D41 -> 253.12577 | E35: =E36+E37+E38+E41 -> 260.44081 | F35: =F36+F37+F38+F41 -> 267.79813 | G35: =G36+G37+G38+G41 -> 281.64044 | H35: =H36+H37+H38+H41 -> 289.17958
B36: I. Gezeichnetes Kapital 131.310.098,00 | C36: 131.3101 | D36: 131.3101 | E36: 131.3101 | F36: 131.3101 | G36: 131.3101 | H36: 131.3101
B37: II. Kapitalrücklage 99.807.492,71 | C37: 99.807493 | D37: 99.807493 | E37: 99.807493 | F37: 99.807493 | G37: 99.807493 | H37: 99.807493
B38: III. Gewinnrücklagen | C38: =C39+C40 -> 19.002115 | D38: =D39+D40 -> 22.008183 | E38: =E39+E40 -> 29.323222 | F38: =F39+F40 -> 36.680539 | G38: =G39+G40 -> 50.522854 | H38: =H39+H40 -> 58.061992
B39: 1. gesetzliche Rücklage 2.845.181,29 | D39: 2.8451813 | E39: 2.8451813 | F39: 2.8451813 | G39: 2.8451813 | H39: 2.8451813
B40: 2. andere Gewinnrücklagen | C40: 19.002115 | D40: 19.163002 | E40: 26.478041 | F40: 33.835357 | G40: 47.677673 | H40: 55.216811
B41: IV. Bilanzgewinn / Bilanzverlust 0,00 | D41: 0 | E41: 0 | F41: 0 | G41: 0 | H41: 0
B43: B. Sonderposten | C43: 1.0916766 | D43: 1.1061198 | E43: 1.4592004 | F43: 1.3594357 | G43: 1.2822406 | H43: 0.82030252
B44: C. Rückstellungen | C44: =C45+C46+C47 -> 180.01188 | D44: =D45+D46+D47 -> 213.37401 | E44: =E45+E46+E47 -> 235.24519 | F44: =F45+F46+F47 -> 231.24569 | G44: =G45+G46+G47 -> 250.50432 | H44: =H45+H46+H47 -> 247.28204
...

Sheet EVM GuV
B2: Energieversorgung Mittelrhein AG – GuV 2020–2025
B3: EUR Mio. | C3: 2020 | D3: =C3+1 -> 2021 | E3: =D3+1 -> 2022 | F3: =E3+1 -> 2023 | G3: =F3+1 -> 2024 | H3: =G3+1 -> 2025
B5: 1. Umsatzerlöse | C5: 699.60987 | D5: 845.45663 | E5: 1174.1012 | F5: 1362.5214 | G5: 1002.158 | H5: 999.2349
B6: 2. Erhöhung / Verminderung des Bestands an fertigen und unfertigen Erzeugnissen | C6: 1.229864 | D6: -0.74918069 | E6: 0.09761003 | F6: -0.05333632 | G6: 0.46086091 | H6: -0.16589166
B7: 3. Andere aktivierte Eigenleistungen | C7: 0 | D7: n.a. | E7: n.a. | F7: n.a. | G7: n.a. | H7: n.a.
B8: 4. Sonstige betriebliche Erträge | C8: 12.771409 | D8: 22.408547 | E8: 25.359661 | F8: 8.7646937 | G8: 4.1842065 | H8: 3.6351163
B9: 5. Materialaufwand | C9: =SUM(C10:C11) -> 561.24352 | D9: =SUM(D10:D11) -> 709.48557 | E9: =SUM(E10:E11) -> 995.12242 | F9: =SUM(F10:F11) -> 1218.8663 | G9: =SUM(G10:G11) -> 817.59624 | H9: =SUM(H10:H11) -> 819.59944
B10: a) Aufwendungen für Roh-, Hilfs- und Betriebsstoffe und für bezogene Waren | C10: 368.83169 | D10: 503.02101 | E10: 776.99894 | F10: 980.60823 | G10: 552.30853 | H10: 528.43758
B11: b) Aufwendungen für bezogene Leistungen | C11: 192.41183 | D11: 206.46456 | E11: 218.12348 | F11: 238.25807 | G11: 265.28771 | H11: 291.16186
B12: 6. Personalaufwand | C12: =SUM(C13:C14) -> 31.740185 | D12: =SUM(D13:D14) -> 39.230848 | E12: =SUM(E13:E14) -> 61.989776 | F12: =SUM(F13:F14) -> 39.555455 | G12: =SUM(G13:G14) -> 43.138652 | H12: =SUM(H13:H14) -> 40.361358
B13: a) Löhne und Gehälter | C13: 27.4897 | D13: 28.224018 | E13: 28.567038 | F13: 30.008774 | G13: 31.272788 | H13: 32.955378
B14: b) Soziale Abgaben und Aufwendungen für Altersversorgung und für Unterstützung | C14: 4.2504848 | D14: 11.00683 | E14: 33.422739 | F14: 9.5466807 | G14: 11.865864 | H14: 7.4059805
B15: davon für Altersversorgung | C15: -0.89235894 | D15: 5.7813639 | E15: 28.066402 | F15: 3.9019989 | G15: 6.142692 | H15: 0.68222389
B16: 7. Abschreibungen auf immaterielle Vermögensgegenstände und Sachanlagen | C16: =C17 -> 19.203884 | D16: =D17 -> 13.047315 | E16: =E17 -> 13.933656 | F16: =F17 -> 14.231203 | G16: =G17 -> 14.417586 | H16: =H17 -> 17.098231
B17: a) auf immaterielle Vermögensgegenstände und Sachanlagen | C17: 19.203884 | D17: 13.047315 | E17: 13.933656 | F17: 14.231203 | G17: 14.417586 | H17: 17.098231
B18: 8. Sonstige betriebliche Aufwendungen | C18: 33.914364 | D18: 38.696636 | E18: 43.991931 | F18: 41.264476 | G18: 55.692153 | H18: 51.419241
B19: 9. Erträge aus Beteiligungen | C19: 1.9961641 | D19: 1.3327278 | E19: 1.2445951 | F19: 5.0312355 | G19: 5.3374268 | H19: 1.4591747
B20: davon aus verbundenen Unternehmen (Beteiligungserträge) | C20: 0.08095393 | D20: 0.0757162 | E20: 0.1150842 | F20: 3.0358681 | G20: 3.6686754 | H20: 0.32103665
B21: 10. Erträge aus Gewinnabführungsverträgen | C21: 15.686735 | D21: 8.3725004 | E21: 8.4842123 | F21: 8.3385357 | G21: 7.02428 | H21: 7.4266401
B22: davon Steuerumlagen | C22: 1.7658551 | D22: 0.508 | E22: n.a. | F22: n.a. | G22: n.a. | H22: 0.5823548
B23: 11. Erträge aus anderen Wertpapieren und Ausleihungen des Finanzanlagevermögens | C23: 0.91049712 | D23: 0.77564882 | E23: 0.22672147 | F23: 0.20935233 | G23: 0.22352573 | H23: 0.49982469
B24: davon aus verbundenen Unternehmen (Finanzanlageerträge) | C24: 0.86802937 | D24: 0.68358353 | E24: 0.22672147 | F24: 0.20935233 | G24: 0.22352573 | H24: 0.08593149
B25: 12. Sonstige Zinsen und ähnliche Erträge | C25: 0.09002878 | D25: 0.1014021 | E25: 0.22580713 | F25: 3.4935237 | G25: 3.6409342 | H25: 3.1391893
B26: 13. Abschreibungen auf Finanzanlagen und auf Wertpapiere des Umlaufvermögens | C26: =IF(ISNUMBER(C27),C27,"n.a.") -> n.a. | D26: =IF(ISNUMBER(D27),D27,"n.a.") -> n.a. | E26: =IF(ISNUMBER(E27),E27,"n.a.") -> n.a. | F26: =IF(ISNUMBER(F27),F27,"n.a.") -> 0.05362635 | G26: =IF(ISNUMBER(G27),G27,"n.a.") -> n.a. | H26: n.a.
B27: davon außerplanmäßige Abschreibungen auf Finanzanlagen | C27: n.a. | D27: n.a. | E27: n.a. | F27: 0.05362635 | G27: n.a. | H27: n.a.
B28: 14. Aufwendungen aus Verlustübernahmen | C28: 10.185035 | D28: 4.3605245 | E28: 14.435237 | F28: n.a. | G28: n.a. | H28: 10.051219
B29: 15. Zinsen und ähnliche Aufwendungen | C29: 11.702316 | D29: 12.817879 | E29: 5.781512 | F29: 3.8797809 | G29: 3.2375696 | H29: 1.2554869
B30: davon an verbundene Unternehmen | C30: 0.05000546 | D30: 0.19521318 | E30: 0.19792533 | F30: 1.7108491 | G30: 1.54699 | H30: 0.70790549
B31: davon aus der Abzinsung | C31: 11.621101 | D31: 12.60904 | E31: 5.274128 | F31: 1.673944 | G31: 1.219573 | H31: 0.08
B32: 16. Steuern vom Einkommen und vom Ertrag | C32: 14.075107 | D32: 9.8658889 | E32: 19.94296 | F32: 15.923835 | G32: 27.934296 | H32: 19.293575
B33: davon Steuerumlagen an den Organträger | C33: 14.894855 | D33: 13.219756 | E33: n.a. | F33: n.a. | G33: n.a. | H33: 20.300359
B35: 17. Ergebnis nach Steuern | C35: =SUM(C5:C8)-C9-C12-C16-C18+SUM(C19,C21,C23,C25)-SUM(C26,C28,C29,C32) -> 50.230157 | D35: =SUM(D5:D8)-D9-D12-D16-D18+SUM(D19,D21,D23,D25)-SUM(D26,D28,D29,D32) -> 50.193617 | E35: =SUM(E5:E8)-E9-E12-E16-E18+SUM(E19,E21,E23,E25)-SUM(E26,E28,E29,E32) -> 54.542344 | F35: =SUM(F5:F8)-F9-F12-F16-F18+SUM(F19,F21,F23,F25)-SUM(F26,F28,F29,F32) -> 54.530778 | G35: =SUM(G5:G8)-G9-G12-G16-G18+SUM(G19,G21,G23,G25)-SUM(G26,G28,G29,G32) -> 61.012745 | H35: =SUM(H5:H8)-H9-H12-H16-H18+SUM(H19,H21,H23,H25)-SUM(H26,H28,H29,H32) -> 56.150409
B36: 18. Sonstige Steuern | C36: 0.18641948 | D36: 0.18754902 | E36: 0.22730471 | F36: 0.17346142 | G36: 0.17042999 | H36: 0.07213264
B37: 19. Abgeführte Gewinne aufgrund eines Gewinnabführungsvertrags | C37: 47 | D37: 47 | E37: 47 | F37: 47 | G37: 47 | H37: 48.539138
B38: 20. Jahresüberschuss | C38: =C35-C36-C37 -> 3.0437373 | D38: =D35-D36-D37 -> 3.0060679 | E38: =E35-E36-E37 -> 7.3150392 | F38: =F35-F36-F37 -> 7.3573167 | G38: =G35-G36-G37 -> 13.842315 | H38: =H35-H36-H37 -> 7.5391381
B40: 21. Einstellungen in Gewinnrücklagen | C40: =C41 -> -3.0437373 | D40: =D41 -> -3.0060679 | E40: =E41 -> 7.3150392 | F40: =F41 -> 7.3573167 | G40: =G41 -> 13.842315 | H40: =H41 -> 7.5391381
B41: a) in andere Gewinnrücklagen | C41: -3.0437373 | D41: -3.0060679 | E41: 7.3150392 | F41: 7.3573167 | G41: 13.842315 | H41: 7.5391381
B43: 22. Bilanzgewinn / Bilanzverlust | C43: =C38-ABS(C40) -> -8.7929664e-14 | D43: =D38-ABS(D40) -> 3.907985e-14 | E43: =E38-ABS(E40) -> -4.4408921e-14 | F43: =F38-ABS(F40) -> 4.4408921e-14 | G43: =G38-ABS(G40) -> -1.9539925e-14 | H43: =H38-ABS(H40) -> 5.9507954e-14
B45: Quelle: EVM-Jahresabschlüsse 2020–2025. Einheitliche Struktur als vollständige Vereinigungsmenge sämtlicher in den Primärabschlüssen ausgewiesener GuV-Positionen. „n.a.“ bedeutet, dass die Position im jeweiligen Jahresabschluss nicht separat ausgewiesen wurde; dies ist nicht mit einem Wert von null gleichzusetzen.

Sheet EVM Cashflow
B2: Energieversorgung Mittelrhein AG - Kapitalflussrechnung 2020 - 2025
B3: EUR Mio. | C3: 2020 | D3: =C3+1 -> 2021 | E3: =D3+1 -> 2022 | F3: =E3+1 -> 2023 | G3: =F3+1 -> 2024 | H3: =G3+1 -> 2025
B5: (+) Cashflow aus laufender Geschäftstätigkeit | C5: 64.502 | D5: 19.969 | E5: 200.708 | F5: -18.566 | G5: 60.789 | H5: 48.858
B6: (+) Cashflow aus der Investitionstätigkeit | C6: -6.681 | D6: -25.314 | E6: -14.953 | F6: -5.502 | G6: -5.878 | H6: -41.741
B7: (+) Cashflow aus der Finanzierungstätigkeit | C7: -47.081 | D7: -47.209 | E7: -27.507 | F7: -37.799 | G7: -49.018 | H7: -48.175
B9: (+) Zahlungswirksame Veränderungen des Finanzmittelfonds | C9: =C5+C6+C7 -> 10.74 | D9: =D5+D6+D7 -> -52.554 | E9: =E5+E6+E7 -> 158.248 | F9: =F5+F6+F7 -> -61.867 | G9: =G5+G6+G7 -> 5.893 | H9: =H5+H6+H7 -> -41.058
B10: (+) Finanzmittelfonds am Jahresanfang | C10: 15.088 | D10: 25.828 | E10: -26.726 | F10: 131.522 | G10: 69.655 | H10: 75.548
B11: Finanzmittelfonds am Jahresende | C11: =C10+C9 -> 25.828 | D11: =D10+D9 -> -26.726 | E11: =E10+E9 -> 131.522 | F11: =F10+F9 -> 69.655 | G11: =G10+G9 -> 75.548 | H11: =H10+H9 -> 34.49
B13: Veränderung der zahlungswirksamen Liquidität | C13: =C9 -> 10.74 | D13: =D9 -> -52.554 | E13: =E9 -> 158.248 | F13: =F9 -> -61.867 | G13: =G9 -> 5.893 | H13: =H9 -> -41.058
B15: Quelle: EVM 2020.pdf bis EVM 2025.pdf. Werte aus den veröffentlichten HGB-Einzelabschlüssen. 2021 wurde zur besseren Konsistenz aus der Vorjahresspalte des Abschlusses 2022 übernommen. Cashflow-Angaben entsprechen den im Lagebericht veröffentlichten Kurzfassungen. 2020/2021 sind aufgrund der Neuallokation von Netzanlagen nur eingeschränkt vergleichbar.

Sheet ENM Bilanz
A1: Energienetze Mittelrhein GmbH & Co. KG – Bilanz 2020–2024
A2: EUR Mio. | B2: 2020 | C2: 2021 | D2: 2022 | E2: 2023 | F2: 2024
A3: A. Anlagevermögen | B3: =B4+B6+B11 -> 125.70562 | C3: =C4+C6+C11 -> 127.72166 | D3: =D4+D6+D11 -> 129.41885 | E3: =E4+E6+E11 -> 133.88151 | F3: =F4+F6+F11 -> 145.09674
A4: I. Immaterielle Vermögensgegenstände | B4: 4.733746 | C4: 4.7732137 | D4: 4.6255638 | E4: 4.3563912 | F4: 4.2840422
A5: 1. entgeltlich erworbene Konzessionen, gewerbliche Schutzrechte und ähnliche Rechte und Werte sowie Lizenzen an solchen Rechten und Werten | B5: 4.733746 | C5: 4.7732137 | D5: 4.6255638 | E5: 4.3563912 | F5: 4.2840422
A6: II. Sachanlagen | B6: =B7+B8+B9+B10 -> 120.94266 | C6: =C7+C8+C9+C10 -> 122.92024 | D6: =D7+D8+D9+D10 -> 124.76588 | E6: =E7+E8+E9+E10 -> 129.49831 | F6: =F7+F8+F9+F10 -> 140.78669
A7: 1. Grundstücke, grundstücksgleiche Rechte und Bauten einschließlich der Bauten auf fremden Grundstücken | B7: 8.9197468 | C7: 8.7515592 | D7: 8.3242948 | E7: 8.0553055 | F7: 8.0936879
A8: 2. technische Anlagen und Maschinen | B8: 102.99963 | C8: 105.3622 | D8: 106.80661 | E8: 108.937 | F8: 116.85709
A9: 3. andere Anlagen, Betriebs- und Geschäftsausstattung | B9: 5.463929 | C9: 5.0306709 | D9: 5.1712583 | E9: 6.5204304 | F9: 9.3577418
A10: 4. geleistete Anzahlungen und Anlagen im Bau | B10: 3.5593572 | C10: 3.7758063 | D10: 4.4637171 | E10: 5.9855732 | F10: 6.4781691
A11: III. Finanzanlagen | B11: =B12+B13 -> 0.02921204 | C11: =C12+C13 -> 0.02820614 | D11: =D12+D13 -> 0.02740644 | E11: =E12+E13 -> 0.02680644 | F11: =F12+F13 -> 0.02600644
A12: 1. Anteile an verbundenen Unternehmen 25.000,00 | B12: 0.025 | C12: 0.025 | D12: 0.025 | E12: 0.025 | F12: 0.025
A13: 2. sonstige Ausleihungen | B13: 0.00421204 | C13: 0.00320614 | D13: 0.00240644 | E13: 0.00180644 | F13: 0.00100644
A14: B. Umlaufvermögen | B14: =B15+B17 -> 62.142292 | C14: =C15+C17 -> 69.86613 | D14: =D15+D17 -> 80.332434 | E14: =E15+E17 -> 79.937595 | F14: =F15+F17 -> 89.37423
A15: I. Vorräte | B15: 3.3015514 | C15: 8.9605032 | D15: 5.5854653 | E15: 5.8646768 | F15: 4.9300473
A16: 1. Roh-, Hilfs- und Betriebsstoffe | B16: 3.1775786 | C16: 4.3117117 | D16: 5.0529638 | E16: 5.2368147 | F16: 4.9300473
A17: II. Forderungen und sonstige Vermögensgegenstände | B17: =B18+B19+B49+B20 -> 58.84074 | C17: =C18+C19+C49+C20 -> 60.905627 | D17: =D18+D19+D49+D20 -> 74.746969 | E17: =E18+E19+E49+E20 -> 74.072918 | F17: =F18+F19+F49+F20 -> 84.444183
A18: 1. Forderungen aus Lieferungen und Leistungen | B18: 14.471457 | C18: 20.651175 | D18: 7.6909167 | E18: 30.792115 | F18: 29.839856
A19: 2. Forderungen gegen nahestehende Unternehmen | B19: 35.144513 | C19: 31.72705 | D19: 52.813768 | E19: 31.378634 | F19: 36.394852
A20: 4. sonstige Vermögensgegenstände | B20: 9.2040738 | C20: 8.4356981 | D20: 14.232799 | E20: 11.897997 | F20: 17.330804
A21: C. Rechnungsabgrenzungsposten | B21: 0.438938 | C21: 0.53062186 | D21: 0.70186947 | E21: 0.72925705 | F21: 0.29839532
A22: Aktiva | B22: =B3+B14+B21 -> 188.28685 | C22: =C3+C14+C21 -> 198.11841 | D22: =D3+D14+D21 -> 210.45315 | E22: =E3+E14+E21 -> 214.54836 | F22: =F3+F14+F21 -> 234.76936
A23: A. Eigenkapital 126.946.671,08 | C23: 126.94667 | D23: 126.94667 | E23: 126.94667 | F23: 126.94667
A24: I. Kapitalanteile 525.000,00 | B24: 0.525 | C24: 0.525 | D24: 0.525 | E24: 0.525 | F24: 0.525
A25: 2. Kapitalanteile Kommanditisten 525.000,00 | B25: 0.525 | C25: 0.525 | D25: 0.525 | E25: 0.525 | F25: 0.525
A26: II. Rücklagen 126.421.671,08 | C26: 126.42167 | D26: 126.42167 | E26: 126.42167 | F26: 126.42167
A27: III. Bilanzgewinn / Bilanzverlust 0,00 | F27: 0
A28: B. Sonderposten | C28: 1.5648471 | D28: 1.4647367 | E28: 1.3672783 | F28: 1.2721533
A29: C. Ausgleichsposten für aktivierte eigene Anteile 25.000,00 | B29: 0.025 | C29: 0.025 | D29: 0.025 | E29: 0.025 | F29: 0.025
A30: D. Rückstellungen | B30: =B31+B32 -> 17.632135 | C30: =C31+C32 -> 22.872135 | D30: =D31+D32 -> 26.17782 | E30: =E31+E32 -> 26.16682 | F30: =F31+F32 -> 33.412596
A31: 1. Steuerrückstellungen | B31: 0.35713476 | C31: 0.08913476 | D31: 0.05081982 | E31: 0.28481982 | F31: 1.2785958
A32: 2. sonstige Rückstellungen | B32: 17.275 | C32: 22.783 | D32: 26.127 | E32: 25.882 | F32: 32.134
A33: E. Verbindlichkeiten | B33: =B34+B36+B38+B40+B42 -> 7.2024468 | C33: =C34+C36+C38+C40+C42 -> 11.160404 | D33: =D34+D36+D38+D40+D42 -> 18.967792 | E33: =E34+E36+E38+E40+E42 -> 20.743557 | F33: =F34+F36+F38+F40+F42 -> 30.363706
A34: 1. erhaltene Anzahlungen auf Bestellungen | B34: 0.2278434 | C34: 0.11337853 | D34: 0.22373154 | E34: 0.12385866 | F34: 0.07865082
A35: davon mit einer Restlaufzeit bis zu einem Jahr | C35: 0.11337853 | D35: 0.22373154 | E35: 0.12385866 | F35: 0.07865082
A36: 2. Verbindlichkeiten aus Lieferungen und Leistungen | B36: 4.2167105 | C36: 8.2888511 | D36: 15.540902 | E36: 15.407556 | F36: 21.997515
A37: davon mit einer Restlaufzeit bis zu einem Jahr | C37: 0.11337853 | D37: 0.22373154 | E37: 0.12385866 | F37: 0.07865082
A38: 3. Verbindlichkeiten gegenüber nahestehenden Unternehmen | B38: 0.40107139 | C38: 0.19725256 | D38: 0.28278892 | E38: 0.61330337 | F38: 0.49066666
A39: davon mit einer Restlaufzeit bis zu einem Jahr | C39: 0.11337853 | D39: 0.22373154 | E39: 0.12385866 | F39: 0.07865082
A40: 4. Verbindlichkeiten gegenüber Gebietskörperschaften | B40: 0.00580524 | C40: 0.09170394 | D40: 0.00948506 | E40: 0.0351884 | F40: 0.87867132
...

Sheet ENM GuV
A1: Energienetze Mittelrhein GmbH & Co. KG – GuV 2020–2024
A2: EUR Mio. | B2: 2020 | C2: 2021 | D2: 2022 | E2: 2023 | F2: 2024
A3: 1. Umsatzerlöse | B3: 311.44739 | C3: 313.00273 | D3: 340.52224 | E3: 407.47916 | F3: 379.54604
A4: 2. Erhöhung / Verminderung des Bestands an unfertigen Erzeugnissen | B4: 0.12397282 | C4: 4.5248187 | D4: -4.11629 | E4: 0.09536057 | F4: -0.62786206
A5: 3. Andere aktivierte Eigenleistungen | B5: 0.00153555 | C5: 3.247405 | D5: 3.0892227 | E5: 3.5583516 | F5: 4.7623469
A6: 4. Sonstige betriebliche Erträge | B6: 0.54079391 | C6: 0.52708116 | D6: 1.5436396 | E6: 7.4100788 | F6: 7.710293
A7: 5. Materialaufwand | B7: =SUM(B8:B9) -> 268.00409 | C7: =SUM(C8:C9) -> 256.07301 | D7: =SUM(D8:D9) -> 280.44969 | E7: =SUM(E8:E9) -> 345.69657 | F7: =SUM(F8:F9) -> 314.33311
A8: a) Aufwendungen für Roh-, Hilfs- und Betriebsstoffe und für bezogene Waren | B8: 62.808476 | C8: 59.777269 | D8: 98.561491 | E8: 141.51845 | F8: 102.72434
A9: b) Aufwendungen für bezogene Leistungen | B9: 205.19561 | C9: 196.29574 | D9: 181.88819 | E9: 204.17811 | F9: 211.60877
A10: 6. Personalaufwand | B10: =SUM(B11:B12) -> 40.818905 | C10: =SUM(C11:C12) -> 47.785298 | D10: =SUM(D11:D12) -> 53.590664 | E10: =SUM(E11:E12) -> 45.766175 | F10: =SUM(F11:F12) -> 47.609984
A11: a) Löhne und Gehälter | B11: 29.82798 | C11: 32.225958 | D11: 31.802365 | E11: 35.434175 | F11: 38.204678
A12: b) Soziale Abgaben und Aufwendungen für Altersversorgung und für Unterstützung | B12: 10.990925 | C12: 15.55934 | D12: 21.7883 | E12: 10.332 | F12: 9.4053061
A13: davon für Altersversorgung | B13: 5.3089955 | C13: 9.238437 | D13: 15.375838 | E13: 3.4082352 | F13: 2.0629434
A14: 7. Abschreibungen auf immaterielle Vermögensgegenstände und Sachanlagen | B14: =B15 -> 1.9692514 | C14: =C15 -> 10.865023 | D14: =D15 -> 11.325085 | E14: =E15 -> 11.865354 | F14: =F15 -> 12.76663
A15: a) auf immaterielle Vermögensgegenstände und Sachanlagen | B15: 1.9692514 | C15: 10.865023 | D15: 11.325085 | E15: 11.865354 | F15: 12.76663
A16: 8. Sonstige betriebliche Aufwendungen | B16: 7.6983375 | C16: 8.0627742 | D16: 9.3524973 | E16: 10.509946 | F16: 10.728412
A17: 9. Sonstige Zinsen und ähnliche Erträge | B17: 0.05177819 | C17: 0.19612075 | D17: 0.19314879 | E17: 1.5782547 | F17: 1.413645
A18: davon aus verbundenen Unternehmen | B18: 0.05002928 | C18: 0.19521318 | D18: 0.18394914 | E18: 1.5782547 | F18: 1.403901
A19: 10. Zinsen und ähnliche Aufwendungen | B19: 0.03083932 | C19: 0.02016632 | D19: 0.04493367 | E19: 0.04340882 | F19: 0.04951137
A20: davon aus der Abzinsung | B20: 0.03 | C20: 0.02 | D20: 0.026 | E20: 0.04340882 | F20: 0.048
A21: 11. Steuern vom Einkommen und vom Ertrag | B21: 3.6902316 | C21: 2.9058261 | D21: 0.75553436 | E21: 3.2018219 | F21: 3.9709069
A22: 12. Ergebnis nach Steuern | B22: =SUM(B3:B6)-B7-B10-B14-B16+B17-B19-B21 -> -10.046184 | C22: =SUM(C3:C6)-C7-C10-C14-C16+C17-C19-C21 -> -4.2139466 | D22: =SUM(D3:D6)-D7-D10-D14-D16+D17-D19-D21 -> -14.286438 | E22: =SUM(E3:E6)-E7-E10-E14-E16+E17-E19-E21 -> 3.0379311 | F22: =SUM(F3:F6)-F7-F10-F14-F16+F17-F19-F21 -> 3.3459125
A23: 13. Sonstige Steuern | B23: 0.13885125 | C23: 0.14657783 | D23: 0.14879932 | E23: 0.14977281 | F23: 0.16430744
A24: 14. Erträge aus Verlustübernahme | B24: 10.185035 | C24: 4.3605245 | D24: 14.435237 | E24: n.a. | F24: n.a.
A25: 15. Jahresüberschuss / -fehlbetrag | B25: =B22-B23+SUM(B24) -> 1.7763568e-14 | C25: =C22-C23+SUM(C24) -> -1.4210855e-14 | D25: =D22-D23+SUM(D24) -> 0 | E25: =E22-E23+SUM(E24) -> 2.8881583 | F25: =F22-F23+SUM(F24) -> 3.1816051
A26: 16. Gutschrift auf Kapitalkonten | B26: n.a. | C26: n.a. | D26: n.a. | E26: 2.8881583 | F26: 3.1816051
A27: 17. Bilanzgewinn / Bilanzverlust | B27: =B25-SUM(B26) -> 1.7763568e-14 | C27: =C25-SUM(C26) -> -1.4210855e-14 | D27: =D25-SUM(D26) -> 0 | E27: =E25-SUM(E26) -> -3.4638958e-14 | F27: =F25-SUM(F26) -> 6.7057471e-14
A29: Quelle: ENM-Jahresabschlüsse 2020–2024. Einheitliche Struktur als vollständige Vereinigungsmenge sämtlicher in den Primärabschlüssen ausgewiesener GuV-Positionen. „n.a.“ bedeutet, dass die Position im jeweiligen Jahresabschluss nicht separat ausgewiesen wurde; dies ist nicht mit einem Wert von null gleichzusetzen.

Sheet ENM Cashflow
A1: Energienetze Mittelrhein GmbH & Co. KG – Kapitalflussrechnung 2020–2024
A2: EUR Mio. | B2: 2020 | C2: 2021 | D2: 2022 | E2: 2023 | F2: 2024
A3: Cashflow aus laufender Geschäftstätigkeit | B3: 14.398 | C3: 0.131 | D3: -9.54 | E3: 4.544 | F3: 14.406
A4: Cashflow aus der Investitionstätigkeit | B4: -2.031 | C4: -9.303 | D4: -9.007 | E4: -11.005 | F4: -17.361
A5: Cashflow aus der Finanzierungstätigkeit | B5: 0 | C5: 9.172 | D5: 18.547 | E5: 6.461 | F5: 2.954
A6: Veränderung der zahlungswirksamen Liquidität | B6: =B3+B4+B5 -> 12.367 | C6: =C3+C4+C5 -> 0 | D6: =D3+D4+D5 -> 0 | E6: =E3+E4+E5 -> 0 | F6: =F3+F4+F5 -> -0.001
A7: Liquidität zum Jahresanfang | B7: 2.028 | C7: 0 | D7: 0 | E7: 0 | F7: 0
A8: Liquidität zum Jahresende | B8: =B7+B6 -> 14.395 | C8: =C7+C6 -> 0 | D8: =D7+D6 -> 0 | E8: =E7+E6 -> 0 | F8: =F7+F6 -> -0.001
A10: Quelle: EN 2020.pdf bis EN 2024.pdf. Werte aus den veröffentlichten HGB-Einzelabschlüssen. 2021 wurde zur besseren Konsistenz aus der Vorjahresspalte des Abschlusses 2022 übernommen. Cashflow-Angaben entsprechen den im Lagebericht veröffentlichten Kurzfassungen. 2020/2021 sind aufgrund der Neuallokation von Netzanlagen nur eingeschränkt vergleichbar.

Sheet EVM KPIs
B2: EVM AG – Key Financials
B3: EUR Mio. / % / x | C3: 2020 | D3: 2021 | E3: 2022 | F3: 2023 | G3: 2024 | H3: 2025
B5: Umsatz | C5: ='EVM GuV'!C5 -> 699.60987 | D5: ='EVM GuV'!D5 -> 845.45663 | E5: ='EVM GuV'!E5 -> 1174.1012 | F5: ='EVM GuV'!F5 -> 1362.5214 | G5: ='EVM GuV'!G5 -> 1002.158 | H5: ='EVM GuV'!H5 -> 999.2349
B6: Gesamtleistung | C6: ='EVM GuV'!C5+SUM('EVM GuV'!C6,'EVM GuV'!C7) -> 700.83973 | D6: ='EVM GuV'!D5+SUM('EVM GuV'!D6,'EVM GuV'!D7) -> 844.70745 | E6: ='EVM GuV'!E5+SUM('EVM GuV'!E6,'EVM GuV'!E7) -> 1174.1988 | F6: ='EVM GuV'!F5+SUM('EVM GuV'!F6,'EVM GuV'!F7) -> 1362.4681 | G6: ='EVM GuV'!G5+SUM('EVM GuV'!G6,'EVM GuV'!G7) -> 1002.6189 | H6: ='EVM GuV'!H5+SUM('EVM GuV'!H6,'EVM GuV'!H7) -> 999.06901
B7: Rohertrag | C7: =C6-'EVM GuV'!C9 -> 139.59621 | D7: =D6-'EVM GuV'!D9 -> 135.22188 | E7: =E6-'EVM GuV'!E9 -> 179.07642 | F7: =F6-'EVM GuV'!F9 -> 143.60181 | G7: =G6-'EVM GuV'!G9 -> 185.02263 | H7: =H6-'EVM GuV'!H9 -> 179.46957
B9: (%) Rohertragsmarge | C9: =IFERROR(C7/C6,0) -> 0.19918422 | D9: =IFERROR(D7/D6,0) -> 0.16008132 | E9: =IFERROR(E7/E6,0) -> 0.15250945 | F9: =IFERROR(F7/F6,0) -> 0.10539829 | G9: =IFERROR(G7/G6,0) -> 0.18453934 | H9: =IFERROR(H7/H6,0) -> 0.17963681
B10: EBITDA | C10: =C6+'EVM GuV'!C8-'EVM GuV'!C9-'EVM GuV'!C12-'EVM GuV'!C18 -> 86.713073 | D10: =D6+'EVM GuV'!D8-'EVM GuV'!D9-'EVM GuV'!D12-'EVM GuV'!D18 -> 79.702945 | E10: =E6+'EVM GuV'!E8-'EVM GuV'!E9-'EVM GuV'!E12-'EVM GuV'!E18 -> 98.454373 | F10: =F6+'EVM GuV'!F8-'EVM GuV'!F9-'EVM GuV'!F12-'EVM GuV'!F18 -> 71.546576 | G10: =G6+'EVM GuV'!G8-'EVM GuV'!G9-'EVM GuV'!G12-'EVM GuV'!G18 -> 90.376031 | H10: =H6+'EVM GuV'!H8-'EVM GuV'!H9-'EVM GuV'!H12-'EVM GuV'!H18 -> 91.324092
B12: EBIT | C12: =C10-'EVM GuV'!C16 -> 67.50919 | D12: =D10-'EVM GuV'!D16 -> 66.65563 | E12: =E10-'EVM GuV'!E16 -> 84.520717 | F12: =F10-'EVM GuV'!F16 -> 57.315373 | G12: =G10-'EVM GuV'!G16 -> 75.958444 | H12: =H10-'EVM GuV'!H16 -> 74.225861
B13: OCF | C13: ='EVM Cashflow'!C5 -> 64.502 | D13: ='EVM Cashflow'!D5 -> 19.969 | E13: ='EVM Cashflow'!E5 -> 200.708 | F13: ='EVM Cashflow'!F5 -> -18.566 | G13: ='EVM Cashflow'!G5 -> 60.789 | H13: ='EVM Cashflow'!H5 -> 48.858
B14: ICF | C14: ='EVM Cashflow'!C6 -> -6.681 | D14: ='EVM Cashflow'!D6 -> -25.314 | E14: ='EVM Cashflow'!E6 -> -14.953 | F14: ='EVM Cashflow'!F6 -> -5.502 | G14: ='EVM Cashflow'!G6 -> -5.878 | H14: ='EVM Cashflow'!H6 -> -41.741
B15: FCF | C15: ='EVM Cashflow'!C7 -> -47.081 | D15: ='EVM Cashflow'!D7 -> -47.209 | E15: ='EVM Cashflow'!E7 -> -27.507 | F15: ='EVM Cashflow'!F7 -> -37.799 | G15: ='EVM Cashflow'!G7 -> -49.018 | H15: ='EVM Cashflow'!H7 -> -48.175
B16: FFCF | C16: =C13+C14 -> 57.821 | D16: =D13+D14 -> -5.345 | E16: =E13+E14 -> 185.755 | F16: =F13+F14 -> -24.068 | G16: =G13+G14 -> 54.911 | H16: =H13+H14 -> 7.117
B18: (%) Eigenkapitalquote | C18: =IFERROR('EVM Bilanz'!C35/'EVM Bilanz'!C33,0) -> 0.42103781 | D18: =IFERROR('EVM Bilanz'!D35/'EVM Bilanz'!D33,0) -> 0.37335501 | E18: =IFERROR('EVM Bilanz'!E35/'EVM Bilanz'!E33,0) -> 0.35337425 | F18: =IFERROR('EVM Bilanz'!F35/'EVM Bilanz'!F33,0) -> 0.36848118 | G18: =IFERROR('EVM Bilanz'!G35/'EVM Bilanz'!G33,0) -> 0.37457217 | H18: =IFERROR('EVM Bilanz'!H35/'EVM Bilanz'!H33,0) -> 0.39108362
B19: (-) Kassenbestand | C19: ='EVM Bilanz'!C31 -> 25.827598 | D19: ='EVM Bilanz'!D31 -> 1.29242 | E19: ='EVM Bilanz'!E31 -> 131.52222 | F19: ='EVM Bilanz'!F31 -> 69.654726 | G19: ='EVM Bilanz'!G31 -> 75.547681 | H19: ='EVM Bilanz'!H31 -> 34.489319
B20: (-) Ford. ggü. verbundene/assoziierte Unternehmen | C20: ='EVM Bilanz'!C29 -> 19.284357 | D20: ='EVM Bilanz'!D29 -> 12.217939 | E20: ='EVM Bilanz'!E29 -> 11.114513 | F20: ='EVM Bilanz'!F29 -> 16.167013 | G20: ='EVM Bilanz'!G29 -> 15.61088 | H20: ='EVM Bilanz'!H29 -> 13.194713
B21: (+) Finanzverbindlichkeiten | C21: =N('EVM Bilanz'!C49) -> 0 | D21: =N('EVM Bilanz'!D49) -> 28.0183 | E21: =N('EVM Bilanz'!E49) -> 20 | F21: =N('EVM Bilanz'!F49) -> 20 | G21: =N('EVM Bilanz'!G49) -> 20 | H21: =N('EVM Bilanz'!H49) -> 20
B22: (+) Pensionsrückstellungen | C22: ='EVM Bilanz'!C45 -> 133.72777 | D22: ='EVM Bilanz'!D45 -> 145.95631 | E22: ='EVM Bilanz'!E45 -> 172.49049 | F22: ='EVM Bilanz'!F45 -> 171.61949 | G22: ='EVM Bilanz'!G45 -> 171.08042 | H22: ='EVM Bilanz'!H45 -> 163.13324
B23: (+) Verb. ggü. verbundene/assoziierte Unternehmen | C23: ='EVM Bilanz'!C55 -> 85.194546 | D23: ='EVM Bilanz'!D55 -> 88.686814 | E23: ='EVM Bilanz'!E55 -> 119.1509 | F23: ='EVM Bilanz'!F55 -> 90.634252 | G23: ='EVM Bilanz'!G55 -> 103.51569 | H23: ='EVM Bilanz'!H55 -> 101.78181
B24: Net Debt | C24: =C23+C22+C21-C20-C19 -> 173.81036 | D24: =D23+D22+D21-D20-D19 -> 249.15106 | E24: =E23+E22+E21-E20-E19 -> 169.00466 | F24: =F23+F22+F21-F20-F19 -> 196.43201 | G24: =G23+G22+G21-G20-G19 -> 203.43755 | H24: =H23+H22+H21-H20-H19 -> 237.23102
B26: Net Debt / EBITDA | C26: =IFERROR(C24/C10,0) -> 2.0044309 | D26: =IFERROR(D24/D10,0) -> 3.1259957 | E26: =IFERROR(E24/E10,0) -> 1.7165785 | F26: =IFERROR(F24/F10,0) -> 2.7455123 | G26: =IFERROR(G24/G10,0) -> 2.2510123 | H26: =IFERROR(H24/H10,0) -> 2.5976827
B27: Capex | C27: ='EVM Capex Revenue'!C7 -> 29.944 | D27: ='EVM Capex Revenue'!D7 -> 29.104 | E27: ='EVM Capex Revenue'!E7 -> 22.865 | F27: ='EVM Capex Revenue'!F7 -> 27.728 | G27: ='EVM Capex Revenue'!G7 -> 24.02 | H27: ='EVM Capex Revenue'!H7 -> 43.148

Sheet EVM Capex Revenue
B2: EVM AG – Capex und Umsatzaufteilung
B3: EUR Mio. | C3: 2020 | D3: 2021 | E3: 2022 | F3: 2023 | G3: 2024 | H3: 2025
B5: Capex
B7: Immaterielle Vermögenswerte und Sachanlagen | C7: 29.944 | D7: 29.104 | E7: 22.865 | F7: 27.728 | G7: 24.02 | H7: 43.148
B8: davon Leitungsnetze | C8: 22.83 | D8: 20.156 | E8: 13.787 | F8: 11.748 | G8: 12.105 | H8: 21.686
B9: Sonstige Capex | C9: =C7-C8 -> 7.114 | D9: =D7-D8 -> 8.948 | E9: =E7-E8 -> 9.078 | F9: =F7-F8 -> 15.98 | G9: =G7-G8 -> 11.915 | H9: =H7-H8 -> 21.462
B12: Umsatzaufteilung nach Tätigkeitsbereichen
B14: Erdgasverkauf | C14: 239.596 | D14: 339.065 | E14: 521.168 | F14: 584.98 | G14: 406.216 | H14: 410.833
B15: Stromverkauf | C15: 361.501 | D15: 411.896 | E15: 543.905 | F15: 670.137 | G15: 489.079 | H15: 479.689
B16: Miet- und Pachterträge | C16: 45.664 | D16: 35.188 | E16: 36.094 | F16: 34.804 | G16: 35.548 | H16: 37.341
B17: Dienstleistungserträge | C17: 23.325 | D17: 23.17 | E17: 23.124 | F17: 24.799 | G17: 28.192 | H17: 28.926
B18: Sonstige | C18: 29.524 | D18: 36.138 | E18: 49.81 | F18: 47.801 | G18: 43.123 | H18: 42.446
B19: Umsatz gesamt | C19: =SUM(C14:C18) -> 699.61 | D19: =SUM(D14:D18) -> 845.457 | E19: =SUM(E14:E18) -> 1174.101 | F19: =SUM(F14:F18) -> 1362.521 | G19: =SUM(G14:G18) -> 1002.158 | H19: =SUM(H14:H18) -> 999.235
B22: Umsatzmix
B24: Erdgasverkauf | C24: =C14/C$19 -> 0.34247081 | D24: =D14/D$19 -> 0.40104346 | E24: =E14/E$19 -> 0.44388685 | F24: =F14/F$19 -> 0.4293365 | G24: =G14/G$19 -> 0.40534127 | H24: =H14/H$19 -> 0.41114753
B25: Stromverkauf | C25: =C15/C$19 -> 0.51671789 | D25: =D15/D$19 -> 0.4871874 | E25: =E15/E$19 -> 0.46325231 | F25: =F15/F$19 -> 0.49183609 | G25: =G15/G$19 -> 0.48802584 | H25: =H15/H$19 -> 0.48005624
B26: Miet- und Pachterträge | C26: =C16/C$19 -> 0.065270651 | D26: =D16/D$19 -> 0.041620094 | E26: =E16/E$19 -> 0.030741819 | F26: =F16/F$19 -> 0.025543826 | G26: =G16/G$19 -> 0.035471453 | H26: =H16/H$19 -> 0.037369588
B27: Dienstleistungserträge | C27: =C17/C$19 -> 0.033340004 | D27: =D17/D$19 -> 0.027405297 | E27: =E17/E$19 -> 0.019695069 | F27: =F17/F$19 -> 0.01820082 | G27: =G17/G$19 -> 0.028131293 | H27: =H17/H$19 -> 0.028948145
B28: Sonstige | C28: =C18/C$19 -> 0.042200655 | D28: =D18/D$19 -> 0.042743747 | E28: =E18/E$19 -> 0.042423948 | F28: =F18/F$19 -> 0.035082762 | G28: =G18/G$19 -> 0.043030141 | H28: =H18/H$19 -> 0.042478496
B31: Quelle: EVM-Jahresabschlüsse 2020–2025, Lagebericht (Investitionen) und Anhang, Erläuterungen zur GuV (Umsatzerlöse nach Tätigkeitsbereichen).

Sheet Netzinfratruktur
B2: Energieversorgung Mittelrhein AG - Ntezlängen der enm
B3: in Kilometer
B4: Spannungsebene | C4: Kabel | D4: Freileitung (km) | E4: Gesamt (km)
B5: Mittelspannung | C5: 1217 | D5: 776 | E5: =+SUM(C5:D5) -> 1993
B6: Niederspannung | C6: 3227 | D6: 2302 | E6: =+SUM(C6:D6) -> 5529
B7: Stromnetz gesamt | C7: =+SUM(C5:C6) -> 4444 | D7: =+SUM(D5:D6) -> 3078 | E7: =+SUM(C7:D7) -> 7522
B10: Erdgasnetz - Rohrnetzlänge
B11: in Kilometer
B12: Druckstufe | C12: Länge
B13: HD-Netz | C13: 919.57
B14: MD-Netz | C14: 2504.88
B15: ND-Netz | C15: 2750.62
B16: Erdgasnetz gesamt | C16: =+SUM(C13:C15) -> 6175.07
B18: Quelle Strom: Energienetze Mittelrhein GmbH & Co. KG, Veröffentlichung nach § 23c Abs. 1 EnWG, Stand 31.12.2025.
B19: Quelle Gas: Energienetze Mittelrhein GmbH & Co. KG, Netzstrukturdaten Erdgas, Stand 31.12.2025.

Sheet ENM KPIs
A1: enm – Key Financials
A2: EUR Mio. / % | B2: 2020 | C2: 2021 | D2: 2022 | E2: 2023 | F2: 2024
A4: Umsatz | B4: ='ENM GuV'!B3 -> 311.44739 | C4: ='ENM GuV'!C3 -> 313.00273 | D4: ='ENM GuV'!D3 -> 340.52224 | E4: ='ENM GuV'!E3 -> 407.47916 | F4: ='ENM GuV'!F3 -> 379.54604
A5: Gesamtleistung | B5: ='ENM GuV'!B3+'ENM GuV'!B4+'ENM GuV'!B5 -> 311.5729 | C5: ='ENM GuV'!C3+'ENM GuV'!C4+'ENM GuV'!C5 -> 320.77495 | D5: ='ENM GuV'!D3+'ENM GuV'!D4+'ENM GuV'!D5 -> 339.49517 | E5: ='ENM GuV'!E3+'ENM GuV'!E4+'ENM GuV'!E5 -> 411.13287 | F5: ='ENM GuV'!F3+'ENM GuV'!F4+'ENM GuV'!F5 -> 383.68053
A6: Rohertrag | B6: =B5-'ENM GuV'!B7 -> 43.568808 | C6: =C5-'ENM GuV'!C7 -> 64.701939 | D6: =D5-'ENM GuV'!D7 -> 59.045489 | E6: =E5-'ENM GuV'!E7 -> 65.436303 | F6: =F5-'ENM GuV'!F7 -> 69.347418
A7: Rohertragsmarge | B7: =IFERROR(B6/B5,0) -> 0.13983504 | C7: =IFERROR(C6/C5,0) -> 0.20170509 | D7: =IFERROR(D6/D5,0) -> 0.17392144 | E7: =IFERROR(E6/E5,0) -> 0.15916096 | F7: =IFERROR(F6/F5,0) -> 0.1807426
A8: EBITDA | B8: =B5+'ENM GuV'!B6-'ENM GuV'!B7-'ENM GuV'!B10-'ENM GuV'!B16 -> -4.4076399 | C8: =C5+'ENM GuV'!C6-'ENM GuV'!C7-'ENM GuV'!C10-'ENM GuV'!C16 -> 9.3809481 | D8: =D5+'ENM GuV'!D6-'ENM GuV'!D7-'ENM GuV'!D10-'ENM GuV'!D16 -> -2.3540333 | E8: =E5+'ENM GuV'!E6-'ENM GuV'!E7-'ENM GuV'!E10-'ENM GuV'!E16 -> 16.570261 | F8: =F5+'ENM GuV'!F6-'ENM GuV'!F7-'ENM GuV'!F10-'ENM GuV'!F16 -> 18.719315
A9: EBIT | B9: =B8-'ENM GuV'!B14 -> -6.3768913 | C9: =C8-'ENM GuV'!C14 -> -1.484075 | D9: =D8-'ENM GuV'!D14 -> -13.679118 | E9: =E8-'ENM GuV'!E14 -> 4.7049072 | F9: =F8-'ENM GuV'!F14 -> 5.9526858
A10: OCF | B10: ='ENM Cashflow'!B3 -> 14.398 | C10: ='ENM Cashflow'!C3 -> 0.131 | D10: ='ENM Cashflow'!D3 -> -9.54 | E10: ='ENM Cashflow'!E3 -> 4.544 | F10: ='ENM Cashflow'!F3 -> 14.406
A11: ICF | B11: ='ENM Cashflow'!B4 -> -2.031 | C11: ='ENM Cashflow'!C4 -> -9.303 | D11: ='ENM Cashflow'!D4 -> -9.007 | E11: ='ENM Cashflow'!E4 -> -11.005 | F11: ='ENM Cashflow'!F4 -> -17.361
A12: FCF | B12: =B10+B11 -> 12.367 | C12: =C10+C11 -> -9.172 | D12: =D10+D11 -> -18.547 | E12: =E10+E11 -> -6.461 | F12: =F10+F11 -> -2.955
A13: Eigenkapitalquote | B13: ='ENM Bilanz'!B23/('ENM Bilanz'!B3+'ENM Bilanz'!B14+'ENM Bilanz'!B21) -> 0 | C13: =IFERROR('ENM Bilanz'!C23/'ENM Bilanz'!C22,0) -> 0.6407616 | D13: =IFERROR('ENM Bilanz'!D23/'ENM Bilanz'!D22,0) -> 0.60320631 | E13: =IFERROR('ENM Bilanz'!E23/'ENM Bilanz'!E22,0) -> 0.59169257 | F13: =IFERROR('ENM Bilanz'!F23/'ENM Bilanz'!F22,0) -> 0.5407293
A14: Capex | B14: ='ENM Capex'!B4 -> 1.379 | C14: ='ENM Capex'!C4 -> 13.01 | D14: ='ENM Capex'!D4 -> 13.193 | E14: ='ENM Capex'!E4 -> 16.373 | F14: ='ENM Capex'!F4 -> 24.156

Sheet ENM Capex
A1: enm – Capex-Entwicklung
A2: EUR Mio. | B2: 2020 | C2: 2021 | D2: 2022 | E2: 2023 | F2: 2024
A4: Investitionen in immaterielle Vermögenswerte und Sachanlagen | B4: 1.379 | C4: 13.01 | D4: 13.193 | E4: 16.373 | F4: 24.156
A6: Die Lageberichte 2021–2024 nennen Leitungsnetze als wesentlichen Investitionsschwerpunkt, veröffentlichen jedoch keine durchgängige quantitative Aufteilung nach Asset-Kategorien. 2020 ohne Zugänge aus der Netzanlagenübertragung.
