Workbook

Sheet Bilanz
A1: ESWE Versorgungs AG, Wiesbaden
A2: Bilanz zum 31. Dezember
A3: HGB-Einzelabschluss – Gliederung gem. § 266 HGB i. V. m. § 265 Abs. 5 und 6 HGB
A4: Angaben in T€
A6: Position | B6: Anhang | C6: 31.12.2020 | D6: 31.12.2021 | E6: 31.12.2022 | F6: 31.12.2023 | G6: 31.12.2024 | H6: 31.12.2025
A8: AKTIVA
A9: A. Anlagevermögen | B9: (1)
A10: I. Immaterielle Vermögensgegenstände | C10: 829 | D10: 1044 | E10: 811 | F10: 658 | G10: 877 | H10: 764
A11: II. Sachanlagen | C11: 159903 | D11: 174058 | E11: 189120 | F11: 197803 | G11: 209240 | H11: 223938
A12: III. Finanzanlagen | C12: 134084 | D12: 148234 | E12: 170186 | F12: 171960 | G12: 165190 | H12: 170025
A13: Anlagevermögen | C13: =SUM(C10:C12) | D13: =SUM(D10:D12) | E13: =SUM(E10:E12) | F13: =SUM(F10:F12) | G13: =SUM(G10:G12) | H13: =SUM(H10:H12)
A15: B. Umlaufvermögen
A16: I. Vorräte | B16: (2) | C16: 3898 | D16: 7162 | E16: 8158 | F16: 15439 | G16: 18356 | H16: 17857
A17: II. Forderungen und sonstige Vermögensgegenstände | B17: (3) | C17: 33013 | D17: 48391 | E17: 17853 | F17: 46747 | G17: 43316 | H17: 63663
A18: III. Kassenbestand und Guthaben bei Kreditinstituten | C18: 2987 | D18: 3616 | E18: 30611 | F18: 44992 | G18: 21543 | H18: 2517
A19: Umlaufvermögen | C19: =SUM(C16:C18) | D19: =SUM(D16:D18) | E19: =SUM(E16:E18) | F19: =SUM(F16:F18) | G19: =SUM(G16:G18) | H19: =SUM(H16:H18)
A21: C. Rechnungsabgrenzungsposten | C21: 2040 | D21: 2468 | E21: 3089 | F21: 3588 | G21: 581 | H21: 819
A22: BILANZSUMME AKTIVA | C22: =C13+C19+C21 | D22: =D13+D19+D21 | E22: =E13+E19+E21 | F22: =F13+F19+F21 | G22: =G13+G19+G21 | H22: =H13+H19+H21
A25: PASSIVA
A26: A. Eigenkapital | B26: (4)
A27: I. Gezeichnetes Kapital | C27: 66013 | D27: 66013 | E27: 66013 | F27: 66013 | G27: 66013 | H27: 66013
A28: II. Kapitalrücklage | C28: 25426 | D28: 25426 | E28: 25426 | F28: 25426 | G28: 25426 | H28: 35426
A29: III. Gewinnrücklagen | C29: 25131 | D29: 25131 | E29: 25131 | F29: 35131 | G29: 35131 | H29: 35131
A30: IV. Bilanzgewinn | C30: 0 | D30: 0 | E30: 0 | F30: 0 | G30: 0 | H30: 0
A31: Eigenkapital | C31: =SUM(C27:C30) | D31: =SUM(D27:D30) | E31: =SUM(E27:E30) | F31: =SUM(F27:F30) | G31: =SUM(G27:G30) | H31: =SUM(H27:H30)
A33: B. Empfangene Ertragszuschüsse | C33: 26940 | D33: 28577 | E33: 28900 | F33: 28009 | G33: 27685 | H33: 29619
A34: C. Rückstellungen | B34: (5) | C34: 80885 | D34: 95422 | E34: 90794 | F34: 111630 | G34: 91974 | H34: 92117
A35: D. Verbindlichkeiten | B35: (6) | C35: 112359 | D35: 144380 | E35: 183564 | F35: 214912 | G35: 212874 | H35: 221277
A36: E. Rechnungsabgrenzungsposten | C36: 0 | D36: 24 | E36: 0 | F36: 66 | G36: 0 | H36: 0
A37: BILANZSUMME PASSIVA | C37: =C31+SUM(C33:C36) | D37: =D31+SUM(D33:D36) | E37: =E31+SUM(E33:E36) | F37: =F31+SUM(F33:F36) | G37: =G31+SUM(G33:G36) | H37: =H31+SUM(H33:H36)
A39: Kontrolle: Bilanzsumme Aktiva ./. Passiva (muss 0 sein) | C39: =C22-C37 | D39: =D22-D37 | E39: =E22-E37 | F39: =F22-F37 | G39: =G22-G37 | H39: =H22-H37
A41: Quelle: Unternehmensregister – ESWE Versorgungs AG, Wiesbaden, HRB 2105.
A42: GJ 2020 und 2021: JA 2021, Seite 10 | GJ 2022: JA 2022, Seite 11–12 | GJ 2023: JA 2023, Seite 1–2 | GJ 2024: JA 2024, Seite 1–2 | GJ 2025: Geschäftsbericht 2025, Seite 73.
A43: Blau = Eingabe direkt aus dem Jahresabschluss | Schwarz = Formel | Sämtliche Zwischen- und Endsummen sind Formeln.

Sheet GuV
A1: ESWE Versorgungs AG, Wiesbaden
A2: Gewinn- und Verlustrechnung
A3: Gesamtkostenverfahren gem. § 275 Abs. 2 HGB – für die Zeit vom 1. Januar bis 31. Dezember
A4: Angaben in T€
A6: Position | B6: Anhang | C6: 2020 | D6: 2021 | E6: 2022 | F6: 2023 | G6: 2024 | H6: 2025
A8: 1. Umsatzerlöse | B8: (10) | C8: 390642 | D8: 426532 | E8: 475683 | F8: 634062 | G8: 534653 | H8: 473770
A9: 2. Veränderung des Bestands an unfertigen Leistungen | C9: -175 | D9: -332 | E9: 860 | F9: 811 | G9: 69 | H9: -545
A10: 3. Andere aktivierte Eigenleistungen | B10: (11) | C10: 2578 | D10: 3399 | E10: 3309 | F10: 1873 | G10: 2674 | H10: 2992
A11: 4. Sonstige betriebliche Erträge | B11: (12) | C11: 2546 | D11: 2486 | E11: 5989 | F11: 6383 | G11: 30279 | H11: 9708
A12: 5. Materialaufwand | B12: (13) | C12: 280935 | D12: 311386 | E12: 356302 | F12: 483927 | G12: 387160 | H12: 341791
A13: 6. Personalaufwand | B13: (14) | C13: 50102 | D13: 50803 | E13: 52128 | F13: 52026 | G13: 55317 | H13: 60837
A14: 7. Abschreibungen | B14: (15) | C14: 13344 | D14: 14180 | E14: 14545 | F14: 14570 | G14: 15673 | H14: 16427
A15: 8. Sonstige betriebliche Aufwendungen | B15: (16) | C15: 28985 | D15: 35338 | E15: 26581 | F15: 49684 | G15: 36261 | H15: 38141
A16: 9. Betriebliches Ergebnis | C16: =SUM(C8:C11)-SUM(C12:C15) | D16: =SUM(D8:D11)-SUM(D12:D15) | E16: =SUM(E8:E11)-SUM(E12:E15) | F16: =SUM(F8:F11)-SUM(F12:F15) | G16: =SUM(G8:G11)-SUM(G12:G15) | H16: =SUM(H8:H11)-SUM(H12:H15)
A17: 10. Beteiligungsergebnis | B17: (17) | C17: 27606 | D17: 24466 | E17: 17558 | F17: 30534 | G17: 17765 | H17: 25060
A18: 11. Abschreibungen auf Finanzanlagen | B18: (18) | C18: 0 | D18: 0 | E18: 2037 | F18: 0 | G18: 8965 | H18: 388
A19: 12. Zinsergebnis | B19: (19) | C19: -2064 | D19: -767 | E19: -49 | F19: 1281 | G19: 2218 | H19: -751
A20: 13. ERGEBNIS VOR STEUERN | C20: =C16+C17-C18+C19 | D20: =D16+D17-D18+D19 | E20: =E16+E17-E18+E19 | F20: =F16+F17-F18+F19 | G20: =G16+G17-G18+G19 | H20: =H16+H17-H18+H19
A21: 14. Steuern vom Einkommen und vom Ertrag | B21: (20) | C21: 3347 | D21: 3034 | E21: 3214 | F21: 3939 | G21: 5544 | H21: 3494
A22: 15. ERGEBNIS NACH STEUERN | C22: =C20-C21 | D22: =D20-D21 | E22: =E20-E21 | F22: =F20-F21 | G22: =G20-G21 | H22: =H20-H21
A23: 16. Sonstige Steuern | B23: (21) | C23: 643 | D23: 300 | E23: 308 | F23: 237 | G23: 440 | H23: 271
A24: 17. UNTERNEHMENSERGEBNIS / JAHRESÜBERSCHUSS | C24: =C22-C23 | D24: =D22-D23 | E24: =E22-E23 | F24: =F22-F23 | G24: =G22-G23 | H24: =H22-H23
A25: 18. Einstellung in die anderen Gewinnrücklagen | B25: (22) | C25: 0 | D25: 0 | E25: 0 | F25: 10000 | G25: 0 | H25: 0
A26: 19. Aufwendungen für Ausgleichszahlung | B26: (23) | C26: 17980 | D26: 16295 | E26: 17312 | F26: 21109 | G26: 29779 | H26: 18768
A27: 20. Aufgrund eines Ergebnisabführungsvertrags abgeführter Gewinn | B27: (24) | C27: 25797 | D27: 24448 | E27: 30923 | F27: 39452 | G27: 48519 | H27: 30117
A28: 21. BILANZGEWINN | C28: =C24-SUM(C25:C27) | D28: =D24-SUM(D25:D27) | E28: =E24-SUM(E25:E27) | F28: =F24-SUM(F25:F27) | G28: =G24-SUM(G25:G27) | H28: =H24-SUM(H25:H27)
A30: Kontrolle: Bilanzgewinn GuV ./. Bilanzgewinn Bilanz (muss 0 sein) | C30: =C28-Bilanz!C30 | D30: =D28-Bilanz!D30 | E30: =E28-Bilanz!E30 | F30: =F28-Bilanz!F30 | G30: =G28-Bilanz!G30 | H30: =H28-Bilanz!H30
A32: Quelle: Unternehmensregister – ESWE Versorgungs AG, Wiesbaden, HRB 2105.
A33: GJ 2020 und 2021: JA 2021, Seite 11 | GJ 2022: JA 2022, Seite 12–13 | GJ 2023: JA 2023, Seite 2 | GJ 2024: JA 2024, Seite 2 | GJ 2025: Geschäftsbericht 2025, Seite 74.
A34: Hinweis GJ 2022: Der JA 2022 weist unter Pos. 16 „Sonstige Steuern“ 307 T€ aus. 48.543 ./. 307 = 48.236, ausgewiesen sind jedoch 48.235 T€.
A35: Der JA 2023 (Seite 23) nennt für 2022 308 T€, womit die Rechnung aufgeht. Angesetzt sind hier 308 T€.
A36: Hinweis GJ 2020/2021: Der JA 2021 kennt die Positionen „Abschreibungen auf Finanzanlagen“ und „Einstellung in die anderen Gewinnrücklagen“ nicht;
A37: sie sind mit 0 angesetzt, damit die Gliederung über alle fünf Jahre einheitlich ist. Die Nummerierung folgt dem JA 2024.

Sheet Kapitalflussrechnung
A1: ESWE Versorgungs AG, Wiesbaden
A2: Kapitalflussrechnung nach DRS 21
A3: Verkürzte Darstellung – die Gesellschaft veröffentlicht die Kapitalflussrechnung nur in dieser Form
A4: Angaben in Mio. €
A6: Position | B6: Anhang | C6: 2020 | D6: 2021 | E6: 2022 | F6: 2023 | G6: 2024 | H6: 2025
A8: Cashflow aus laufender Geschäftstätigkeit | C8: n. v. | D8: 49 | E8: 78 | F8: 47.3 | G8: 68.2 | H8: 42.7
A9: Cashflow aus Investitionstätigkeit | C9: 1.7 | D9: -19.5 | E9: -34 | F9: 8.9 | G9: -5 | H9: -8.3
A10: Cashflow aus Finanzierungstätigkeit | C10: -46.8 | D10: -28.9 | E10: -17 | F10: -41.8 | G10: -86.7 | H10: -53.4
A11: Zahlungswirksame Veränderung des Finanzmittelfonds | C11: =IF(COUNT(C8:C10)=3,SUM(C8:C10),"n. v.") | D11: =IF(COUNT(D8:D10)=3,SUM(D8:D10),"n. v.") | E11: =IF(COUNT(E8:E10)=3,SUM(E8:E10),"n. v.") | F11: =IF(COUNT(F8:F10)=3,SUM(F8:F10),"n. v.") | G11: =IF(COUNT(G8:G10)=3,SUM(G8:G10),"n. v.") | H11: =IF(COUNT(H8:H10)=3,SUM(H8:H10),"n. v.")
A13: Finanzmittelfonds am Anfang der Periode | C13: n. v. | D13: 3 | E13: 3.6 | F13: 30.6 | G13: 45 | H13: 21.5
A14: Finanzmittelfonds am Ende der Periode | C14: =IF(AND(ISNUMBER(C13),ISNUMBER(C11)),C13+C11,"n. v.") | D14: =IF(AND(ISNUMBER(D13),ISNUMBER(D11)),D13+D11,"n. v.") | E14: =IF(AND(ISNUMBER(E13),ISNUMBER(E11)),E13+E11,"n. v.") | F14: =IF(AND(ISNUMBER(F13),ISNUMBER(F11)),F13+F11,"n. v.") | G14: =IF(AND(ISNUMBER(G13),ISNUMBER(G11)),G13+G11,"n. v.") | H14: =IF(AND(ISNUMBER(H13),ISNUMBER(H11)),H13+H11,"n. v.")
A16: nachrichtlich: veröffentlichter Endbestand lt. Lagebericht | C16: 3 | D16: 3.6 | E16: 30.6 | F16: 45 | G16: 21.5 | H16: 2.5
A17: Kontrolle: berechneter ./. veröffentlichter Endbestand (muss 0 sein) | C17: =IF(ISNUMBER(C14),ROUND(C14-C16,1),"n. v.") | D17: =IF(ISNUMBER(D14),ROUND(D14-D16,1),"n. v.") | E17: =IF(ISNUMBER(E14),ROUND(E14-E16,1),"n. v.") | F17: =IF(ISNUMBER(F14),ROUND(F14-F16,1),"n. v.") | G17: =IF(ISNUMBER(G14),ROUND(G14-G16,1),"n. v.") | H17: =IF(ISNUMBER(H14),ROUND(H14-H16,1),"n. v.")
A18: Kontrolle: Endbestand ./. Kassenbestand lt. Bilanz (muss 0 sein) | C18: =IF(ISNUMBER(C14),ROUND(C14-Bilanz!C18/1000,1),"n. v.") | D18: =IF(ISNUMBER(D14),ROUND(D14-Bilanz!D18/1000,1),"n. v.") | E18: =IF(ISNUMBER(E14),ROUND(E14-Bilanz!E18/1000,1),"n. v.") | F18: =IF(ISNUMBER(F14),ROUND(F14-Bilanz!F18/1000,1),"n. v.") | G18: =IF(ISNUMBER(G14),ROUND(G14-Bilanz!G18/1000,1),"n. v.") | H18: =IF(ISNUMBER(H14),ROUND(H14-Bilanz!H18/1000,1),"n. v.")
A20: Quelle: Lagebericht im jeweiligen Jahresabschluss – JA 2023 Seite 25, JA 2024 Seite 26, Geschäftsbericht 2025 Seite 18; GJ 2021 und 2022 aus dem Lageberichtstext.
A21: Eine Überleitung der einzelnen DRS-21-Posten (Jahresergebnis, Abschreibungen, Working-Capital-Veränderungen usw.) ist aus den
A22: veröffentlichten Abschlüssen nicht ableitbar – die Gesellschaft legt nur die drei Cashflow-Salden offen.
A23: GJ 2020: Der JA 2021 nennt als Vorjahreswerte nur Investitions- und Finanzierungscashflow; der laufende Cashflow ist nicht beziffert (n. v.).
A24: GJ 2022: Der JA 2022 nennt im Lagebericht 95,4 / -44,9 / -23,5 Mio. €, der JA 2023 für dasselbe Jahr 78,0 / -34,0 / -17,0 Mio. €.
A25: Die Summe (27,0 Mio. €) ist in beiden Fassungen identisch – es handelt sich um eine Umgliederung. Angesetzt sind die Werte des JA 2023.

Sheet Anhang & Capex
A1: ESWE Versorgungs AG, Wiesbaden
A2: Ergänzende Angaben aus Anhang und Lagebericht
A3: Grundlage für Net Debt und Capex – zeilengetreu aus den Anhangangaben (3), (5), (6) und der Investitionsübersicht im Lagebericht
A4: Angaben in T€
A6: Position | B6: Anhang | C6: 31.12.2020 | D6: 31.12.2021 | E6: 31.12.2022 | F6: 31.12.2023 | G6: 31.12.2024 | H6: 31.12.2025
A8: Verschuldungskomponenten
A9: Verbindlichkeiten gegenüber Kreditinstituten | B9: (6) | C9: 66060 | D9: 79000 | E9: 98659 | F9: 110748 | G9: 119911 | H9: 124179
A10: Rückstellungen für Pensionen und ähnliche Verpflichtungen | B10: (5) | C10: 8866 | D10: 9041 | E10: 9230 | F10: 9213 | G10: 8483 | H10: 8066
A11: Verbindlichkeiten gegenüber verbundenen Unternehmen | B11: (6) | C11: 955 | D11: 10250 | E11: 14709 | F11: 9310 | G11: 24487 | H11: 26903
A12: Verbindlichkeiten gegenüber Unternehmen, mit denen ein Beteiligungsverhältnis besteht | B12: (6) | C12: 20153 | D12: 18608 | E12: 22424 | F12: 24293 | G12: 32764 | H12: 20741
A13: davon gegenüber Gesellschafter (Ausgleichszahlung Thüga AG) | B13: (6) | C13: 17980 | D13: 16295 | E13: 17312 | F13: 21109 | G13: 29779 | H13: 18768
A14: Forderungen gegen verbundene Unternehmen | B14: (3) | C14: 12234 | D14: 11518 | E14: 6763 | F14: 7033 | G14: 4521 | H14: 7716
A15: Forderungen gegen Unternehmen, mit denen ein Beteiligungsverhältnis besteht | B15: (3) | C15: 3071 | D15: 3658 | E15: 3656 | F15: 2410 | G15: 3379 | H15: 5977
A17: Übrige Verbindlichkeitenposten (nur zur Abstimmung gegen die Bilanz)
A18: Erhaltene Anzahlungen | B18: (6) | C18: 57 | D18: 0 | E18: 0 | F18: 0 | G18: 0 | H18: 0
A19: Verbindlichkeiten aus Lieferungen und Leistungen | B19: (6) | C19: 20507 | D19: 25196 | E19: 42633 | F19: 44546 | G19: 29531 | H19: 40796
A20: Sonstige Verbindlichkeiten | B20: (6) | C20: 4627 | D20: 11326 | E20: 5139 | F20: 26015 | G20: 6182 | H20: 8658
A21: Summe Verbindlichkeiten laut Anhang | C21: =C9+C11+C12+SUM(C18:C20) | D21: =D9+D11+D12+SUM(D18:D20) | E21: =E9+E11+E12+SUM(E18:E20) | F21: =F9+F11+F12+SUM(F18:F20) | G21: =G9+G11+G12+SUM(G18:G20) | H21: =H9+H11+H12+SUM(H18:H20)
A22: nachrichtlich: Verbindlichkeiten laut Bilanz | C22: =Bilanz!C35 | D22: =Bilanz!D35 | E22: =Bilanz!E35 | F22: =Bilanz!F35 | G22: =Bilanz!G35 | H22: =Bilanz!H35
A23: Kontrolle: Anhang ./. Bilanz (muss 0 sein) | C23: =C21-C22 | D23: =D21-D22 | E23: =E21-E22 | F23: =F21-F22 | G23: =G21-G22 | H23: =H21-H22
A25: Gesamtinvestitionen nach Unternehmensbereichen (Lagebericht)
A26: Stromversorgung | C26: 2885 | D26: 2876 | E26: 2173 | F26: 524 | G26: 568 | H26: 982
A27: Gasversorgung | C27: 14161 | D27: 9439 | E27: 4249 | F27: 2139 | G27: 2393 | H27: 2991
A28: Wasserversorgung | C28: 4482 | D28: 7505 | E28: 11746 | F28: 5922 | G28: 7867 | H28: 13969
A29: Wärmeversorgung | C29: 4281 | D29: 7456 | E29: 8593 | F29: 9995 | G29: 8561 | H29: 6503
A30: Telekommunikation | C30: 0 | D30: 0 | E30: 0 | F30: 919 | G30: 1259 | H30: 0
A31: Sonstige Bereiche | C31: 1160 | D31: 1748 | E31: 1059 | F31: 376 | G31: 1173 | H31: 3377
A32: Gemeinsame Bereiche | C32: 0 | D32: 0 | E32: 1851 | F32: 5599 | G32: 3426 | H32: 3957
A33: Beteiligungen (Finanzanlagen) | C33: 1735 | D33: 14169 | E33: 24003 | F33: 1868 | G33: 2206 | H33: 5229
A34: Gesamtinvestitionen (inkl. Finanzanlagen) | C34: =SUM(C26:C33) | D34: =SUM(D26:D33) | E34: =SUM(E26:E33) | F34: =SUM(F26:F33) | G34: =SUM(G26:G33) | H34: =SUM(H26:H33)
A35: Sach- und immaterielle Investitionen (ohne Finanzanlagen) | C35: =C34-C33 | D35: =D34-D33 | E35: =E34-E33 | F35: =F34-F33 | G35: =G34-G33 | H35: =H34-H33
A36: nachrichtlich: ausgewiesene Summe laut Lagebericht | C36: 28704 | D36: 43193 | E36: 53674 | F36: 27342 | G36: 27453 | H36: 37008
A37: Kontrolle: Summe der Bereiche ./. ausgewiesene Summe (muss 0 sein) | C37: =C34-C36 | D37: =D34-D36 | E37: =E34-E36 | F37: =F34-F36 | G37: =G34-G36 | H37: =H34-H36
A39: Eigenkapitalquote laut Lagebericht (zur Kontrolle)
A40: Eigenkapitalquote laut Lagebericht | C40: 0.346 | D40: 0.303 | E40: 0.278 | F40: 0.263 | G40: 0.276 | H40: 0.285
A42: Quellen: Anhangangaben (3) Forderungen, (5) Rückstellungen und (6) Verbindlichkeiten sowie Investitionsübersicht im Lagebericht.
A43: GJ 2020: JA 2021, Seiten 14–17, 22 | GJ 2021: JA 2021 bzw. JA 2022 | GJ 2022: JA 2022 / JA 2023 | GJ 2023: JA 2023 / JA 2024 | GJ 2024: JA 2024, Seiten 5–8, 25 | GJ 2025: Geschäftsbericht 2025, Seiten 18, 80–82.
A44: Vorjahreswerte sind jeweils der Fassung des jüngeren Abschlusses entnommen (siehe Blatt „Quellen & Hinweise“, Abweichungen 4 bis 7).
A45: Blau = Eingabe direkt aus dem Abschluss | Schwarz = Formel | Grün = Verweis auf ein anderes Blatt | Sämtliche Summen sind Formeln.

Sheet Overview FS
A1: ESWE Versorgungs AG, Wiesbaden
A2: Overview Financial Statements 2020 – 2025
A3: Alle Werte sind Verweise (grün) auf die Blätter Bilanz, GuV, Kapitalflussrechnung und „Anhang & Capex“ – keine Doppelerfassung; Kennzahlen sind Formeln (schwarz)
A4: Angaben in T€, sofern nicht anders vermerkt
A6: Position | B6: Anhang | C6: 2020 | D6: 2021 | E6: 2022 | F6: 2023 | G6: 2024 | H6: 2025
A8: Ertragslage
A9: Umsatzerlöse | C9: =GuV!C8 | D9: =GuV!D8 | E9: =GuV!E8 | F9: =GuV!F8 | G9: =GuV!G8 | H9: =GuV!H8
A10: Umsatzwachstum in % | C10: n. v. | D10: =D9/C9-1 | E10: =E9/D9-1 | F10: =F9/E9-1 | G10: =G9/F9-1 | H10: =H9/G9-1
A11: Veränderung des Bestands an unfertigen Leistungen | C11: =GuV!C9 | D11: =GuV!D9 | E11: =GuV!E9 | F11: =GuV!F9 | G11: =GuV!G9 | H11: =GuV!H9
A12: Andere aktivierte Eigenleistungen | C12: =GuV!C10 | D12: =GuV!D10 | E12: =GuV!E10 | F12: =GuV!F10 | G12: =GuV!G10 | H12: =GuV!H10
A13: Gesamtleistung | C13: =C9+C11+C12 | D13: =D9+D11+D12 | E13: =E9+E11+E12 | F13: =F9+F11+F12 | G13: =G9+G11+G12 | H13: =H9+H11+H12
A14: Materialaufwand | C14: =GuV!C12 | D14: =GuV!D12 | E14: =GuV!E12 | F14: =GuV!F12 | G14: =GuV!G12 | H14: =GuV!H12
A15: Rohertrag | C15: =C13-C14 | D15: =D13-D14 | E15: =E13-E14 | F15: =F13-F14 | G15: =G13-G14 | H15: =H13-H14
A16: Rohertrag-Marge in % | C16: =C15/C9 | D16: =D15/D9 | E16: =E15/E9 | F16: =F15/F9 | G16: =G15/G9 | H16: =H15/H9
A17: Personalaufwand | C17: =GuV!C13 | D17: =GuV!D13 | E17: =GuV!E13 | F17: =GuV!F13 | G17: =GuV!G13 | H17: =GuV!H13
A18: Abschreibungen auf immat. Vermögensgegenstände und Sachanlagen | C18: =GuV!C14 | D18: =GuV!D14 | E18: =GuV!E14 | F18: =GuV!F14 | G18: =GuV!G14 | H18: =GuV!H14
A19: Sonstige betriebliche Erträge | C19: =GuV!C11 | D19: =GuV!D11 | E19: =GuV!E11 | F19: =GuV!F11 | G19: =GuV!G11 | H19: =GuV!H11
A20: Sonstige betriebliche Aufwendungen | C20: =GuV!C15 | D20: =GuV!D15 | E20: =GuV!E15 | F20: =GuV!F15 | G20: =GuV!G15 | H20: =GuV!H15
A21: EBIT / Betriebliches Ergebnis | C21: =GuV!C16 | D21: =GuV!D16 | E21: =GuV!E16 | F21: =GuV!F16 | G21: =GuV!G16 | H21: =GuV!H16
A22: EBIT-Marge in % | C22: =C21/C9 | D22: =D21/D9 | E22: =E21/E9 | F22: =F21/F9 | G22: =G21/G9 | H22: =H21/H9
A23: EBITDA (Betriebliches Ergebnis + Abschreibungen) | C23: =C21+C18 | D23: =D21+D18 | E23: =E21+E18 | F23: =F21+F18 | G23: =G21+G18 | H23: =H21+H18
A24: EBITDA-Marge in % | C24: =C23/C9 | D24: =D23/D9 | E24: =E23/E9 | F24: =F23/F9 | G24: =G23/G9 | H24: =H23/H9
A25: Beteiligungsergebnis | C25: =GuV!C17 | D25: =GuV!D17 | E25: =GuV!E17 | F25: =GuV!F17 | G25: =GuV!G17 | H25: =GuV!H17
A26: EBITDA inkl. Beteiligungsergebnis | C26: =C23+C25 | D26: =D23+D25 | E26: =E23+E25 | F26: =F23+F25 | G26: =G23+G25 | H26: =H23+H25
A27: Zinsergebnis | C27: =GuV!C19 | D27: =GuV!D19 | E27: =GuV!E19 | F27: =GuV!F19 | G27: =GuV!G19 | H27: =GuV!H19
A28: Ergebnis vor Steuern (EBT) | C28: =GuV!C20 | D28: =GuV!D20 | E28: =GuV!E20 | F28: =GuV!F20 | G28: =GuV!G20 | H28: =GuV!H20
A29: EAT / Unternehmensergebnis (vor Ergebnisabführung) | C29: =GuV!C24 | D29: =GuV!D24 | E29: =GuV!E24 | F29: =GuV!F24 | G29: =GuV!G24 | H29: =GuV!H24
A30: EAT-Marge in % | C30: =C29/C9 | D30: =D29/D9 | E30: =E29/E9 | F30: =F29/F9 | G30: =G29/G9 | H30: =H29/H9
A31: Einstellung in die anderen Gewinnrücklagen | C31: =-GuV!C25 | D31: =-GuV!D25 | E31: =-GuV!E25 | F31: =-GuV!F25 | G31: =-GuV!G25 | H31: =-GuV!H25
A32: Ausgleichszahlung an die Thüga AG | C32: =-GuV!C26 | D32: =-GuV!D26 | E32: =-GuV!E26 | F32: =-GuV!F26 | G32: =-GuV!G26 | H32: =-GuV!H26
A33: Gewinnabführung an die WVV Wiesbaden Holding GmbH | C33: =-GuV!C27 | D33: =-GuV!D27 | E33: =-GuV!E27 | F33: =-GuV!F27 | G33: =-GuV!G27 | H33: =-GuV!H27
A34: Bilanzgewinn | C34: =GuV!C28 | D34: =GuV!D28 | E34: =GuV!E28 | F34: =GuV!F28 | G34: =GuV!G28 | H34: =GuV!H28
A36: Investitionen
A37: Gesamtinvestitionen (inkl. Finanzanlagen) | C37: ='Anhang & Capex'!C34 | D37: ='Anhang & Capex'!D34 | E37: ='Anhang & Capex'!E34 | F37: ='Anhang & Capex'!F34 | G37: ='Anhang & Capex'!G34 | H37: ='Anhang & Capex'!H34
A38: davon Finanzanlagen | C38: ='Anhang & Capex'!C33 | D38: ='Anhang & Capex'!D33 | E38: ='Anhang & Capex'!E33 | F38: ='Anhang & Capex'!F33 | G38: ='Anhang & Capex'!G33 | H38: ='Anhang & Capex'!H33
A39: Sach- und immaterielle Investitionen | C39: =C37-C38 | D39: =D37-D38 | E39: =E37-E38 | F39: =F37-F38 | G39: =G37-G38 | H39: =H37-H38
A40: Gesamtinvestitionen / Umsatz in % | C40: =C37/C9 | D40: =D37/D9 | E40: =E37/E9 | F40: =F37/F9 | G40: =G37/G9 | H40: =H37/H9
A42: Finanzlage (Mio. €)
A43: Operating Cash Flow | C43: =Kapitalflussrechnung!C8 | D43: =Kapitalflussrechnung!D8 | E43: =Kapitalflussrechnung!E8 | F43: =Kapitalflussrechnung!F8 | G43: =Kapitalflussrechnung!G8 | H43: =Kapitalflussrechnung!H8
A44: Investing Cash Flow | C44: =Kapitalflussrechnung!C9 | D44: =Kapitalflussrechnung!D9 | E44: =Kapitalflussrechnung!E9 | F44: =Kapitalflussrechnung!F9 | G44: =Kapitalflussrechnung!G9 | H44: =Kapitalflussrechnung!H9
...

Sheet Quellen & Hinweise
A1: Quellen und Hinweise
A3: Gesellschaft | B3: ESWE Versorgungs AG, Wiesbaden – Amtsgericht Wiesbaden, HRB 2105
A4: Quelle | B4: Auszüge aus dem Unternehmensregister (offengelegte Jahres- und Tätigkeitsabschlüsse nach EnWG) sowie Geschäftsbericht 2025 der Gesellschaft
A6: JA 2021 | B6: GJ 01.01.–31.12.2021, Tag der Erstellung 13.02.2023 – liefert GJ 2021 und Vorjahr 2020
A7: JA 2022 | B7: GJ 01.01.–31.12.2022, Tag der Erstellung 29.02.2024 – liefert GJ 2022 (und Vorjahreswerte 2021)
A8: JA 2023 | B8: GJ 01.01.–31.12.2023, Tag der Erstellung 03.02.2025 – liefert GJ 2023 (und Vorjahreswerte 2022)
A9: JA 2024 | B9: GJ 01.01.–31.12.2024, Tag der Erstellung 16.01.2026 – liefert GJ 2024 (und Vorjahreswerte 2023)
A10: GB 2025 | B10: Geschäftsbericht 2025 mit vollständigem Jahresabschluss zum 31.12.2025 (Bilanz S. 73, GuV S. 74, Anhang S. 75–86, Bestätigungsvermerk KPMG S. 87) – liefert GJ 2025
A12: Abgrenzung | B12: Dargestellt ist ausschließlich der HGB-Einzelabschluss der ESWE Versorgungs AG.
B13: Die Tätigkeitsabschlüsse nach § 6b EnWG (Elektrizitätsverteilung, Gasverteilung, Messstellenbetrieb,
B14: öffentliche Infrastruktur) sind nicht Bestandteil dieser Auswertung.
B15: Ein Konzernabschluss wird nicht aufgestellt (§ 291 Abs. 1 HGB – Einbeziehung in den Konzernabschluss
B16: der WVV Wiesbaden Holding GmbH). Beteiligungen sind daher nur zu Buchwerten und über das Beteiligungsergebnis abgebildet;
B17: die operative Größe der Gruppe (u. a. sw netz, WiTCOM, ESWE BioEnergie, KMW) ist nirgends konsolidiert verfügbar.
A19: Farbkonvention | B19: Blau = Eingabewert direkt aus dem Abschluss | Schwarz = Formel im Blatt | Grün = Verweis auf anderes Blatt
B20: Sämtliche Zwischen- und Endsummen sind als Formeln hinterlegt und nirgends hartcodiert.
A22: Einheiten | B22: Bilanz, GuV, Anhang & Capex und die Ertrags-/Verschuldungsblöcke des Overview FS in T€.
B23: Die Kapitalflussrechnung wird von der Gesellschaft nur in Mio. € veröffentlicht und ist im Modell durchgehend in Mio. € geführt.
B24: Auf den Folien werden alle Beträge in Mio. € gezeigt; die Umrechnung erfolgt ausschließlich im Output-Blatt.
A26: Kennzahlen | B26: Rohertrag = Gesamtleistung (Umsatz + Bestandsveränderung + aktivierte Eigenleistungen) ./. Materialaufwand.
B27: EBITDA = Betriebliches Ergebnis + Abschreibungen auf immaterielle Vermögensgegenstände und Sachanlagen (Pos. 7 der GuV);
B28: das Beteiligungsergebnis ist NICHT enthalten. Da es bei ESWE 17–31 Mio. € p. a. beträgt und im Wesentlichen aus
B29: Gewinnabführungen der Töchter und der KMW-Ausschüttung stammt, ist zusätzlich „EBITDA inkl. Beteiligungsergebnis“ ausgewiesen.
B30: EAT = Unternehmensergebnis/Jahresüberschuss nach Steuern, vor Ausgleichszahlung an die Thüga AG und vor Gewinnabführung an die WVV.
B31: Net Debt = Verbindlichkeiten gegenüber Kreditinstituten + Pensionsrückstellungen + Verbindlichkeiten gegenüber verbundenen
B32: Unternehmen und gegenüber Unternehmen, mit denen ein Beteiligungsverhältnis besteht ./. Kassenbestand ./. Forderungen gegen
B33: verbundene Unternehmen ./. Forderungen gegen Unternehmen, mit denen ein Beteiligungsverhältnis besteht.
B34: Damit enthalten sind auch die zum Stichtag noch nicht ausgezahlte Gewinnabführung und Ausgleichszahlung (31.12.2024: 29,8 Mio. €
B35: Ausgleichszahlung Thüga; 31.12.2025: 18,8 Mio. €). Empfangene Ertragszuschüsse sind nicht enthalten (kein Fremdkapitalcharakter).
B36: Capex = Gesamtinvestitionen laut Lagebericht inkl. Finanzanlagen, zusätzlich ohne Finanzanlagen ausgewiesen.
A38: Abweichung 1 | B38: JA 2022, Seite 12: Pos. 16 „Sonstige Steuern“ 2022 mit 307 T€ ausgewiesen. 48.543 ./. 307 = 48.236,
B39: ausgewiesen sind jedoch 48.235 T€. Der JA 2023, Seite 23, nennt für 2022 308 T€. Angesetzt: 308 T€.
A40: Abweichung 2 | B40: Kapitalflussrechnung 2022: JA 2022 nennt 95,4 / -44,9 / -23,5 Mio. €, JA 2023 für dasselbe Jahr
B41: 78,0 / -34,0 / -17,0 Mio. €. Die Summe (27,0 Mio. €) ist identisch – Umgliederung zwischen den
B42: Cashflow-Bereichen. Angesetzt sind die Werte des JA 2023.
A43: Abweichung 3 | B43: GJ 2020: Der laufende Cashflow wird im JA 2021 nur qualitativ beschrieben und nicht beziffert (n. v.).
A44: Abweichung 4 | B44: Investitionen nach Bereichen 2023: JA 2023 weist Stromversorgung 1.005 T€ und Sonstige Bereiche 814 T€ aus, ohne eigene Zeile
B45: Telekommunikation. Der JA 2024 nennt für dasselbe Jahr Strom 524 T€, Telekommunikation 919 T€ und Sonstige 376 T€.
B46: Die Gesamtsumme (27.342 T€) ist identisch – Umgliederung. Angesetzt ist die Fassung des JA 2024.
A47: Abweichung 5 | B47: Verbindlichkeiten 31.12.2024: Die Einzelposten des Anhangs (6) summieren sich auf 212.875 T€; ausgewiesen und in der Bilanz
...
