Workbook

Sheet Cover
B2: ‹Gesellschaft› – Financial Model ‹J1›–‹J5›
B4: ‹HGB-Einzelabschluss / Konzernabschluss› · Geschäftsjahre ‹J1› bis ‹J5›
B5: Alle Beträge in Mio. EUR, sofern nicht anders vermerkt
B7: Inhalt | C7: Inhalt / Beschreibung
B8: Overview FS | C8: Verdichtete Ertrags-, Finanz- und Vermögenslage sowie Kennzahlen 2021–2025
B9: GES Bilanz | C9: Bilanz zum 31. Dezember, Gliederung gem. § 266 HGB
B10: GES GuV | C10: Gewinn- und Verlustrechnung, Gesamtkostenverfahren gem. § 275 Abs. 2 HGB
B11: GES Cashflow | C11: Kapitalflussrechnung nach DRS 21 (veröffentlichte Kurzfassung)
B12: GES KPIs | C12: Key Financials – Marge, EBITDA, Net Debt, Eigenkapitalquote, Capex
B13: GES Capex Revenue | C13: Investitionen und Umsatzerlöse nach Unternehmensbereichen, Absatzmengen
B14: Quellen & Hinweise | C14: Quellenverzeichnis, Farbkonvention, Abweichungen und Umgliederungen
B16: Farbkonvention
B17: Blau | C17: Eingabewert direkt aus dem Jahresabschluss bzw. Geschäftsbericht
B18: Schwarz | C18: Formel innerhalb des Blattes
B19: Grün | C19: Verweis auf ein anderes Blatt dieser Mappe
B20: Grau kursiv | C20: Position im betreffenden Jahr nicht separat ausgewiesen (n.a.)
B22: Sämtliche Zwischen- und Endsummen sind Formeln. Overview FS trägt rechts die think-cell-Blöcke je Folienobjekt. Definitionen nach Einheit (EBIT/EBITDA) und Net-Debt-Stufe stehen als Schalter auf dem KPI-Blatt und wortgleich in Quellen & Hinweise.
B24: Erstes Geschäftsjahr | C24: 2021 | D24: blau = Eingabe; alle Jahreszeilen der Mappe hängen daran

Sheet Output>>

Sheet Overview FS
B2: ‹Gesellschaft› – Financial Overview 2021–2025 | J2: think-cell-Blöcke: je Block ein Folienobjekt. Block inklusive Kopfzeile markieren und in think-cell einfügen. Alle Zellen sind Verweise.
B3: Mio. EUR / % / x | C3: =Cover!$C$24 | D3: =C3+1 | E3: =D3+1 | F3: =E3+1 | G3: =F3+1
B4: Umsatzerlöse | C4: ='GES KPIs'!C5 | D4: ='GES KPIs'!D5 | E4: ='GES KPIs'!E5 | F4: ='GES KPIs'!F5 | G4: ='GES KPIs'!G5 | J4: GuV-Chart (Financials Block 1) | K4: =$C$3 | L4: =$D$3 | M4: =$E$3 | N4: =$F$3 | O4: =$G$3
B5: Gesamtleistung | C5: ='GES KPIs'!C6 | D5: ='GES KPIs'!D6 | E5: ='GES KPIs'!E6 | F5: ='GES KPIs'!F6 | G5: ='GES KPIs'!G6 | J5: Umsatzerlöse | K5: =C4 | L5: =D4 | M5: =E4 | N5: =F4 | O5: =G4
B6: Rohertrag | C6: ='GES KPIs'!C7 | D6: ='GES KPIs'!D7 | E6: ='GES KPIs'!E7 | F6: ='GES KPIs'!F7 | G6: ='GES KPIs'!G7 | J6: Rohertrag | K6: =C6 | L6: =D6 | M6: =E6 | N6: =F6 | O6: =G6
B7: Rohertragsmarge | C7: ='GES KPIs'!C8 | D7: ='GES KPIs'!D8 | E7: ='GES KPIs'!E8 | F7: ='GES KPIs'!F8 | G7: ='GES KPIs'!G8 | J7: EBITDA | K7: =C8 | L7: =D8 | M7: =E8 | N7: =F8 | O7: =G8
B8: EBITDA (für Folie, Definition nach Einheit) | C8: ='GES KPIs'!C52 | D8: ='GES KPIs'!D52 | E8: ='GES KPIs'!E52 | F8: ='GES KPIs'!F52 | G8: ='GES KPIs'!G52 | J8: Rohertrag-Marge | K8: =C7 | L8: =D7 | M8: =E7 | N8: =F7 | O8: =G7
B9: Betriebliches Ergebnis | C9: ='GES KPIs'!C11 | D9: ='GES KPIs'!D11 | E9: ='GES KPIs'!E11 | F9: ='GES KPIs'!F11 | G9: ='GES KPIs'!G11 | J9: EBITDA-Marge | K9: ='GES KPIs'!C53 | L9: ='GES KPIs'!D53 | M9: ='GES KPIs'!E53 | N9: ='GES KPIs'!F53 | O9: ='GES KPIs'!G53
B10: Beteiligungsergebnis | C10: ='GES KPIs'!C12 | D10: ='GES KPIs'!D12 | E10: ='GES KPIs'!E12 | F10: ='GES KPIs'!F12 | G10: ='GES KPIs'!G12 | J10: CAGR Umsatzerlöse J1–J5 | K10: ='GES KPIs'!C67
B11: Ergebnis vor Steuern | C11: ='GES KPIs'!C14 | D11: ='GES KPIs'!D14 | E11: ='GES KPIs'!E14 | F11: ='GES KPIs'!F14 | G11: ='GES KPIs'!G14
B12: Jahresüberschuss | C12: ='GES KPIs'!C15 | D12: ='GES KPIs'!D15 | E12: ='GES KPIs'!E15 | F12: ='GES KPIs'!F15 | G12: ='GES KPIs'!G15 | J12: Cashflow-Chart (Financials Block 2) | K12: =$C$3 | L12: =$D$3 | M12: =$E$3 | N12: =$F$3 | O12: =$G$3
J13: Operating Cashflow | K13: =C15 | L13: =D15 | M13: =E15 | N13: =F15 | O13: =G15
B14: Cashflow | C14: =C3 | D14: =D3 | E14: =E3 | F14: =F3 | G14: =G3 | J14: Investing Cashflow | K14: =C16 | L14: =D16 | M14: =E16 | N14: =F16 | O14: =G16
B15: Operating Cash Flow | C15: ='GES KPIs'!C17 | D15: ='GES KPIs'!D17 | E15: ='GES KPIs'!E17 | F15: ='GES KPIs'!F17 | G15: ='GES KPIs'!G17 | J15: Financing Cashflow | K15: =C17 | L15: =D17 | M15: =E17 | N15: =F17 | O15: =G17
B16: Investing Cash Flow | C16: ='GES KPIs'!C18 | D16: ='GES KPIs'!D18 | E16: ='GES KPIs'!E18 | F16: ='GES KPIs'!F18 | G16: ='GES KPIs'!G18 | J16: Total Cashflow | K16: =C18 | L16: =D18 | M16: =E18 | N16: =F18 | O16: =G18
B17: Financing Cash Flow | C17: ='GES KPIs'!C19 | D17: ='GES KPIs'!D19 | E17: ='GES KPIs'!E19 | F17: ='GES KPIs'!F19 | G17: ='GES KPIs'!G19
B18: Cashflow gesamt | C18: =SUM(C15:C17) | D18: =SUM(D15:D17) | E18: =SUM(E15:E17) | F18: =SUM(F15:F17) | G18: =SUM(G15:G17) | J18: Bilanz-Chart (Financials Block 3) | K18: =$C$3 | L18: =$D$3 | M18: =$E$3 | N18: =$F$3 | O18: =$G$3
J19: Liquide Mittel | K19: =C24 | L19: =D24 | M19: =E24 | N19: =F24 | O19: =G24
B20: Vermögens- und Finanzlage | C20: =C3 | D20: =D3 | E20: =E3 | F20: =F3 | G20: =G3 | J20: Net Debt | K20: =C26 | L20: =D26 | M20: =E26 | N20: =F26 | O20: =G26
B21: Bilanzsumme | C21: ='GES KPIs'!C22 | D21: ='GES KPIs'!D22 | E21: ='GES KPIs'!E22 | F21: ='GES KPIs'!F22 | G21: ='GES KPIs'!G22 | J21: Eigenkapital-Quote | K21: =C23 | L21: =D23 | M21: =E23 | N21: =F23 | O21: =G23
B22: Eigenkapital | C22: ='GES KPIs'!C23 | D22: ='GES KPIs'!D23 | E22: ='GES KPIs'!E23 | F22: ='GES KPIs'!F23 | G22: ='GES KPIs'!G23
B23: Eigenkapitalquote | C23: ='GES KPIs'!C24 | D23: ='GES KPIs'!D24 | E23: ='GES KPIs'!E24 | F23: ='GES KPIs'!F24 | G23: ='GES KPIs'!G24 | J23: Verschuldung (Investitionsfolie links) | K23: =$C$3 | L23: =$D$3 | M23: =$E$3 | N23: =$F$3 | O23: =$G$3
B24: Kassenbestand | C24: ='GES KPIs'!C27 | D24: ='GES KPIs'!D27 | E24: ='GES KPIs'!E27 | F24: ='GES KPIs'!F27 | G24: ='GES KPIs'!G27 | J24: Net Debt | K24: =C26 | L24: =D26 | M24: =E26 | N24: =F26 | O24: =G26
B25: Finanzverbindlichkeiten | C25: ='GES KPIs'!C28 | D25: ='GES KPIs'!D28 | E25: ='GES KPIs'!E28 | F25: ='GES KPIs'!F28 | G25: ='GES KPIs'!G28 | J25: Net Debt / EBITDA | K25: =C27 | L25: =D27 | M25: =E27 | N25: =F27 | O25: =G27
B26: Net Debt (für Folie, Stufe lt. KPI-Blatt) | C26: ='GES KPIs'!C64 | D26: ='GES KPIs'!D64 | E26: ='GES KPIs'!E64 | F26: ='GES KPIs'!F64 | G26: ='GES KPIs'!G64
B27: Net Debt / EBITDA | C27: ='GES KPIs'!C65 | D27: ='GES KPIs'!D65 | E27: ='GES KPIs'!E65 | F27: ='GES KPIs'!F65 | G27: ='GES KPIs'!G65 | J27: Kacheln (Kunden und Netz, native Textfelder) | K27: =$G$3 | L27: =$F$3
B28: Capex (Gesamtinvestitionen) | C28: ='GES KPIs'!C32 | D28: ='GES KPIs'!D32 | E28: ='GES KPIs'!E32 | F28: ='GES KPIs'!F32 | G28: ='GES KPIs'!G32 | J28: Stromkunden / Stromabsatz | K28: ='GES KPIs'!G70 | L28: ='GES KPIs'!F70
J29: Gaskunden / Gasabsatz | K29: ='GES KPIs'!G71 | L29: ='GES KPIs'!F71
B30: Umsatzaufteilung | C30: =C3 | D30: =D3 | E30: =E3 | F30: =F3 | G30: =G3 | J30: Stromnetz km | K30: ='GES KPIs'!G72 | L30: ='GES KPIs'!F72
B31: Stromversorgung (inkl. Handelsgeschäfte) | C31: ='GES Capex Revenue'!C24 | D31: ='GES Capex Revenue'!D24 | E31: ='GES Capex Revenue'!E24 | F31: ='GES Capex Revenue'!F24 | G31: ='GES Capex Revenue'!G24 | J31: Gasnetz km | K31: ='GES KPIs'!G73 | L31: ='GES KPIs'!F73
B32: Gasversorgung (inkl. Handelsgeschäfte) | C32: ='GES Capex Revenue'!C25 | D32: ='GES Capex Revenue'!D25 | E32: ='GES Capex Revenue'!E25 | F32: ='GES Capex Revenue'!F25 | G32: ='GES Capex Revenue'!G25 | J32: Umsatz (Mio. EUR) | K32: =G4 | L32: =F4
B33: Wärmeversorgung | C33: ='GES Capex Revenue'!C26 | D33: ='GES Capex Revenue'!D26 | E33: ='GES Capex Revenue'!E26 | F33: ='GES Capex Revenue'!F26 | G33: ='GES Capex Revenue'!G26 | J33: EBITDA (Mio. EUR) | K33: =G8 | L33: =F8
B34: Betriebsführung Wasserversorgung | C34: ='GES Capex Revenue'!C27 | D34: ='GES Capex Revenue'!D27 | E34: ='GES Capex Revenue'!E27 | F34: ='GES Capex Revenue'!F27 | G34: ='GES Capex Revenue'!G27 | J34: EBIT (Mio. EUR) | K34: ='GES KPIs'!G51 | L34: ='GES KPIs'!F51
B35: Wasserverkauf an ‹Eigenbetrieb› | C35: ='GES Capex Revenue'!C28 | D35: ='GES Capex Revenue'!D28 | E35: ='GES Capex Revenue'!E28 | F35: ='GES Capex Revenue'!F28 | G35: ='GES Capex Revenue'!G28 | J35: EAT (Mio. EUR) | K35: ='GES KPIs'!G54 | L35: ='GES KPIs'!F54
B36: Konzerninterne Dienstleistungen | C36: ='GES Capex Revenue'!C29 | D36: ='GES Capex Revenue'!D29 | E36: ='GES Capex Revenue'!E29 | F36: ='GES Capex Revenue'!F29 | G36: ='GES Capex Revenue'!G29 | J36: CapEx (Mio. EUR) | K36: =G28 | L36: =F28
B37: Übrige Umsatzerlöse | C37: ='GES Capex Revenue'!C30 | D37: ='GES Capex Revenue'!D30 | E37: ='GES Capex Revenue'!E30 | F37: ='GES Capex Revenue'!F30 | G37: ='GES Capex Revenue'!G30 | J37: Mitarbeiter | K37: ='GES KPIs'!G74 | L37: ='GES KPIs'!F74
B38: Umsätze lt. GuV | C38: =SUM(C31:C37) | D38: =SUM(D31:D37) | E38: =SUM(E31:E37) | F38: =SUM(F31:F37) | G38: =SUM(G31:G37)
J39: Umsatzring (Kunden und Netz, think-cell) | K39: =$G$3 | L39: Anteil
B40: Anteil Strom / Gas am Umsatz | C40: =IFERROR((C31+C32)/C38,0) | D40: =IFERROR((D31+D32)/D38,0) | E40: =IFERROR((E31+E32)/E38,0) | F40: =IFERROR((F31+F32)/F38,0) | G40: =IFERROR((G31+G32)/G38,0) | J40: ='GES Capex Revenue'!B24 | K40: ='GES Capex Revenue'!G24 | L40: ='GES Capex Revenue'!G36
J41: ='GES Capex Revenue'!B25 | K41: ='GES Capex Revenue'!G25 | L41: ='GES Capex Revenue'!G37
...

Sheet Input>>

Sheet GES Bilanz
B2: ‹Gesellschaft› – Bilanz zum 31. Dezember 2021–2025
B3: Mio. EUR | C3: =Cover!$C$24 | D3: =C3+1 | E3: =D3+1 | F3: =E3+1 | G3: =F3+1
B5: AKTIVA
B6: A. Anlagevermögen (1) | C6: =SUM(C7:C9) | D6: =SUM(D7:D9) | E6: =SUM(E7:E9) | F6: =SUM(F7:F9) | G6: =SUM(G7:G9)
B7: I. Immaterielle Vermögensgegenstände
B8: II. Sachanlagen
B9: III. Finanzanlagen
B11: B. Umlaufvermögen | C11: =SUM(C12:C14) | D11: =SUM(D12:D14) | E11: =SUM(E12:E14) | F11: =SUM(F12:F14) | G11: =SUM(G12:G14)
B12: I. Vorräte (2)
B13: II. Forderungen und sonstige Vermögensgegenstände (3)
B14: III. Kassenbestand und Guthaben bei Kreditinstituten
B16: C. Rechnungsabgrenzungsposten
B17: Bilanzsumme Aktiva | C17: =C6+C11+C16 | D17: =D6+D11+D16 | E17: =E6+E11+E16 | F17: =F6+F11+F16 | G17: =G6+G11+G16
B19: PASSIVA
B20: A. Eigenkapital (4) | C20: =SUM(C21:C24) | D20: =SUM(D21:D24) | E20: =SUM(E21:E24) | F20: =SUM(F21:F24) | G20: =SUM(G21:G24)
B21: I. Gezeichnetes Kapital
B22: II. Kapitalrücklage
B23: III. Gewinnrücklagen
B24: IV. Bilanzgewinn
B26: B. Empfangene Ertragszuschüsse
B27: C. Rückstellungen (5)
B28: D. Verbindlichkeiten (6)
B29: davon gegenüber Kreditinstituten
B30: E. Rechnungsabgrenzungsposten
B31: Bilanzsumme Passiva | C31: =C20+C26+C27+C28+C30 | D31: =D20+D26+D27+D28+D30 | E31: =E20+E26+E27+E28+E30 | F31: =F20+F26+F27+F28+F30 | G31: =G20+G26+G27+G28+G30
B33: Kontrolle: Bilanzsumme Aktiva ./. Passiva (muss 0 sein) | C33: =ROUND(C17-C31,6) | D33: =ROUND(D17-D31,6) | E33: =ROUND(E17-E31,6) | F33: =ROUND(F17-F31,6) | G33: =ROUND(G17-G31,6)
B35: Quelle: Unternehmensregister – ‹Gesellschaft›, ‹Stadt›, HRB 2105 (Amtsgericht ‹Stadt›): Jahresabschluss 2021 (GJ 2021), 2022 (GJ 2022), 2023 (GJ 2023) und 2024 (GJ 2024); Geschäftsbericht 2025, Seite 73 (GJ 2025). Beträge in Tausend EUR veröffentlicht und hier in Mio. EUR dargestellt. Die Position „davon gegenüber Kreditinstituten“ stammt aus dem Verbindlichkeitenspiegel im Anhang (JA 2021 S. 17, JA 2022 S. 18, JA 2023 S. 8, JA 2024 S. 7, GB 2025 S. 82) und ist nachrichtlich ausgewiesen; sie geht nicht in die Bilanzsumme ein.

Sheet GES GuV
B2: ‹Gesellschaft› – Gewinn- und Verlustrechnung 2021–2025
B3: Mio. EUR | C3: =Cover!$C$24 | D3: =C3+1 | E3: =D3+1 | F3: =E3+1 | G3: =F3+1
B5: 1. Umsatzerlöse (10)
B6: 2. Veränderung des Bestands an unfertigen Leistungen
B7: 3. Andere aktivierte Eigenleistungen (11)
B8: 4. Sonstige betriebliche Erträge (12)
B9: 5. Materialaufwand (13)
B10: 6. Personalaufwand (14)
B11: 7. Abschreibungen (15)
B12: 8. Sonstige betriebliche Aufwendungen (16)
B13: 9. Betriebliches Ergebnis | C13: =SUM(C5:C8)-SUM(C9:C12) | D13: =SUM(D5:D8)-SUM(D9:D12) | E13: =SUM(E5:E8)-SUM(E9:E12) | F13: =SUM(F5:F8)-SUM(F9:F12) | G13: =SUM(G5:G8)-SUM(G9:G12)
B15: 10. Beteiligungsergebnis (17)
B16: 11. Abschreibungen auf Finanzanlagen (18)
B17: 12. Zinsergebnis (19)
B18: 13. Ergebnis vor Steuern | C18: =C13+C15-C16+C17 | D18: =D13+D15-D16+D17 | E18: =E13+E15-E16+E17 | F18: =F13+F15-F16+F17 | G18: =G13+G15-G16+G17
B20: 14. Steuern vom Einkommen und vom Ertrag (20)
B21: 15. Ergebnis nach Steuern | C21: =C18-C20 | D21: =D18-D20 | E21: =E18-E20 | F21: =F18-F20 | G21: =G18-G20
B23: 16. Sonstige Steuern (21)
B24: 17. Unternehmensergebnis / Jahresüberschuss | C24: =C21-C23 | D24: =D21-D23 | E24: =E21-E23 | F24: =F21-F23 | G24: =G21-G23
B26: 18. Einstellung in die anderen Gewinnrücklagen (22)
B27: 19. Aufwendungen für Ausgleichszahlung
B28: 20. Aufgrund eines Ergebnisabführungsvertrags abgeführter Gewinn
B29: 21. Bilanzgewinn | C29: =ROUND(C24-SUM(C26:C28),6) | D29: =ROUND(D24-SUM(D26:D28),6) | E29: =ROUND(E24-SUM(E26:E28),6) | F29: =ROUND(F24-SUM(F26:F28),6) | G29: =ROUND(G24-SUM(G26:G28),6)
B31: Kontrolle: Bilanzgewinn GuV ./. Bilanzgewinn Bilanz (muss 0 sein) | C31: =ROUND(C29-'GES Bilanz'!C24,6) | D31: =ROUND(D29-'GES Bilanz'!D24,6) | E31: =ROUND(E29-'GES Bilanz'!E24,6) | F31: =ROUND(F29-'GES Bilanz'!F24,6) | G31: =ROUND(G29-'GES Bilanz'!G24,6)
B33: Quelle: Unternehmensregister – ‹Gesellschaft›, HRB 2105, Jahresabschlüsse 2021 bis 2024; Geschäftsbericht 2025, Seite 74 (GJ 2025). Die Positionsnummerierung folgt dem Jahresabschluss 2024. Die Gewinn- und Verlustrechnung 2025 weist die Position „Einstellung in die anderen Gewinnrücklagen“ nicht aus; sie ist für 2025 mit null angesetzt, wodurch die Gliederung über alle fünf Jahre einheitlich bleibt und der Bilanzgewinn in jedem Jahr auf null überleitet.

Sheet GES Cashflow
B2: ‹Gesellschaft› – Kapitalflussrechnung nach DRS 21 2021–2025
B3: Mio. EUR | C3: =Cover!$C$24 | D3: =C3+1 | E3: =D3+1 | F3: =E3+1 | G3: =F3+1
B5: (+) Cashflow aus laufender Geschäftstätigkeit
B6: (+) Cashflow aus der Investitionstätigkeit
B7: (+) Cashflow aus der Finanzierungstätigkeit
B9: (=) Zahlungswirksame Veränderung des Finanzmittelfonds | C9: =SUM(C5:C7) | D9: =SUM(D5:D7) | E9: =SUM(E5:E7) | F9: =SUM(F5:F7) | G9: =SUM(G5:G7)
B10: (+) Finanzmittelfonds am Anfang der Periode
B11: Finanzmittelfonds am Ende der Periode | C11: =C10+C9 | D11: =D10+D9 | E11: =E10+E9 | F11: =F10+F9 | G11: =G10+G9
B13: nachrichtlich: veröffentlichter Endbestand lt. Lagebericht
B14: Kontrolle: berechneter ./. veröffentlichter Endbestand (muss 0 sein) | C14: =ROUND(C11-C13,1) | D14: =ROUND(D11-D13,1) | E14: =ROUND(E11-E13,1) | F14: =ROUND(F11-F13,1) | G14: =ROUND(G11-G13,1)
B15: Kontrolle: Endbestand ./. Kassenbestand lt. Bilanz (muss 0 sein) | C15: =ROUND(C11-'GES Bilanz'!C14,1) | D15: =ROUND(D11-'GES Bilanz'!D14,1) | E15: =ROUND(E11-'GES Bilanz'!E14,1) | F15: =ROUND(F11-'GES Bilanz'!F14,1) | G15: =ROUND(G11-'GES Bilanz'!G14,1)
B17: Quelle: Lagebericht im jeweiligen Jahresabschluss (JA 2022 für GJ 2021 und 2022, JA 2023 S. 25, JA 2024 S. 26) sowie Geschäftsbericht 2025, Seite 18 (GJ 2024 und 2025). Die Gesellschaft veröffentlicht die Kapitalflussrechnung ausschließlich in dieser verkürzten Form; eine Überleitung der einzelnen DRS-21-Posten (Jahresergebnis, Abschreibungen, Working-Capital-Veränderungen usw.) ist aus den veröffentlichten Abschlüssen nicht ableitbar. Für 2022 nennt der JA 2022 abweichend 95,4 / -44,9 / -23,5 Mio. EUR; angesetzt sind die Werte des JA 2023 – die Summe ist in beiden Fassungen identisch (Umgliederung).

Sheet GES KPIs
B2: ‹Gesellschaft› – Key Financials 2021–2025
B3: Mio. EUR / % / x | C3: =Cover!$C$24 | D3: =C3+1 | E3: =D3+1 | F3: =E3+1 | G3: =F3+1
B5: Umsatzerlöse | C5: ='GES GuV'!C5 | D5: ='GES GuV'!D5 | E5: ='GES GuV'!E5 | F5: ='GES GuV'!F5 | G5: ='GES GuV'!G5
B6: Gesamtleistung | C6: ='GES GuV'!C5+'GES GuV'!C6+'GES GuV'!C7 | D6: ='GES GuV'!D5+'GES GuV'!D6+'GES GuV'!D7 | E6: ='GES GuV'!E5+'GES GuV'!E6+'GES GuV'!E7 | F6: ='GES GuV'!F5+'GES GuV'!F6+'GES GuV'!F7 | G6: ='GES GuV'!G5+'GES GuV'!G6+'GES GuV'!G7
B7: Rohertrag | C7: =C6-'GES GuV'!C9 | D7: =D6-'GES GuV'!D9 | E7: =E6-'GES GuV'!E9 | F7: =F6-'GES GuV'!F9 | G7: =G6-'GES GuV'!G9
B8: (%) Rohertragsmarge | C8: =IFERROR(C7/C6,0) | D8: =IFERROR(D7/D6,0) | E8: =IFERROR(E7/E6,0) | F8: =IFERROR(F7/F6,0) | G8: =IFERROR(G7/G6,0)
B10: EBITDA | C10: =C11+'GES GuV'!C11 | D10: =D11+'GES GuV'!D11 | E10: =E11+'GES GuV'!E11 | F10: =F11+'GES GuV'!F11 | G10: =G11+'GES GuV'!G11
B11: EBIT / Betriebliches Ergebnis | C11: ='GES GuV'!C13 | D11: ='GES GuV'!D13 | E11: ='GES GuV'!E13 | F11: ='GES GuV'!F13 | G11: ='GES GuV'!G13
B12: Beteiligungsergebnis | C12: ='GES GuV'!C15 | D12: ='GES GuV'!D15 | E12: ='GES GuV'!E15 | F12: ='GES GuV'!F15 | G12: ='GES GuV'!G15
B13: Zinsergebnis | C13: ='GES GuV'!C17 | D13: ='GES GuV'!D17 | E13: ='GES GuV'!E17 | F13: ='GES GuV'!F17 | G13: ='GES GuV'!G17
B14: Ergebnis vor Steuern | C14: ='GES GuV'!C18 | D14: ='GES GuV'!D18 | E14: ='GES GuV'!E18 | F14: ='GES GuV'!F18 | G14: ='GES GuV'!G18
B15: Jahresüberschuss | C15: ='GES GuV'!C24 | D15: ='GES GuV'!D24 | E15: ='GES GuV'!E24 | F15: ='GES GuV'!F24 | G15: ='GES GuV'!G24
B17: OCF – Operating Cash Flow | C17: ='GES Cashflow'!C5 | D17: ='GES Cashflow'!D5 | E17: ='GES Cashflow'!E5 | F17: ='GES Cashflow'!F5 | G17: ='GES Cashflow'!G5
B18: ICF – Investing Cash Flow | C18: ='GES Cashflow'!C6 | D18: ='GES Cashflow'!D6 | E18: ='GES Cashflow'!E6 | F18: ='GES Cashflow'!F6 | G18: ='GES Cashflow'!G6
B19: FCF – Financing Cash Flow | C19: ='GES Cashflow'!C7 | D19: ='GES Cashflow'!D7 | E19: ='GES Cashflow'!E7 | F19: ='GES Cashflow'!F7 | G19: ='GES Cashflow'!G7
B20: FFCF – Free Cash Flow (OCF + ICF) | C20: =C17+C18 | D20: =D17+D18 | E20: =E17+E18 | F20: =F17+F18 | G20: =G17+G18
B22: Bilanzsumme | C22: ='GES Bilanz'!C17 | D22: ='GES Bilanz'!D17 | E22: ='GES Bilanz'!E17 | F22: ='GES Bilanz'!F17 | G22: ='GES Bilanz'!G17
B23: Eigenkapital | C23: ='GES Bilanz'!C20 | D23: ='GES Bilanz'!D20 | E23: ='GES Bilanz'!E20 | F23: ='GES Bilanz'!F20 | G23: ='GES Bilanz'!G20
B24: (%) Eigenkapitalquote | C24: =IFERROR(C23/C22,0) | D24: =IFERROR(D23/D22,0) | E24: =IFERROR(E23/E22,0) | F24: =IFERROR(F23/F22,0) | G24: =IFERROR(G23/G22,0)
B25: (%) Anlagenintensität | C25: =IFERROR('GES Bilanz'!C6/C22,0) | D25: =IFERROR('GES Bilanz'!D6/D22,0) | E25: =IFERROR('GES Bilanz'!E6/E22,0) | F25: =IFERROR('GES Bilanz'!F6/F22,0) | G25: =IFERROR('GES Bilanz'!G6/G22,0)
B26: (%) Umsatzrendite | C26: =IFERROR(C15/C5,0) | D26: =IFERROR(D15/D5,0) | E26: =IFERROR(E15/E5,0) | F26: =IFERROR(F15/F5,0) | G26: =IFERROR(G15/G5,0)
B27: (-) Kassenbestand | C27: ='GES Bilanz'!C14 | D27: ='GES Bilanz'!D14 | E27: ='GES Bilanz'!E14 | F27: ='GES Bilanz'!F14 | G27: ='GES Bilanz'!G14
B28: (+) Verbindlichkeiten gegenüber Kreditinstituten | C28: ='GES Bilanz'!C29 | D28: ='GES Bilanz'!D29 | E28: ='GES Bilanz'!E29 | F28: ='GES Bilanz'!F29 | G28: ='GES Bilanz'!G29
B29: Net Debt | C29: =C28-C27 | D29: =D28-D27 | E29: =E28-E27 | F29: =F28-F27 | G29: =G28-G27
B30: Net Debt / EBITDA | C30: =IFERROR(C29/C10,0) | D30: =IFERROR(D29/D10,0) | E30: =IFERROR(E29/E10,0) | F30: =IFERROR(F29/F10,0) | G30: =IFERROR(G29/G10,0)
B32: Capex (Gesamtinvestitionen inkl. Finanzanlagen) | C32: ='GES Capex Revenue'!C14 | D32: ='GES Capex Revenue'!D14 | E32: ='GES Capex Revenue'!E14 | F32: ='GES Capex Revenue'!F14 | G32: ='GES Capex Revenue'!G14
B33: (%) Capex / Umsatzerlöse | C33: =IFERROR(C32/C5,0) | D33: =IFERROR(D32/D5,0) | E33: =IFERROR(E32/E5,0) | F33: =IFERROR(F32/F5,0) | G33: =IFERROR(G32/G5,0)
B35: Absatzmengen | C35: =C3 | D35: =D3 | E35: =E3 | F35: =F3 | G35: =G3
B36: Absatzmengen (aus Capex Revenue) | C36: ='GES Capex Revenue'!C18 | D36: ='GES Capex Revenue'!D18 | E36: ='GES Capex Revenue'!E18 | F36: ='GES Capex Revenue'!F18 | G36: ='GES Capex Revenue'!G18
B37: Gas (Mio. kWh) | C37: ='GES Capex Revenue'!C19 | D37: ='GES Capex Revenue'!D19 | E37: ='GES Capex Revenue'!E19 | F37: ='GES Capex Revenue'!F19 | G37: ='GES Capex Revenue'!G19
B38: Wärme / Kälte (Mio. kWh) | C38: ='GES Capex Revenue'!C20 | D38: ='GES Capex Revenue'!D20 | E38: ='GES Capex Revenue'!E20 | F38: ='GES Capex Revenue'!F20 | G38: ='GES Capex Revenue'!G20
B39: Wassernetz (Mio. m³) | C39: ='GES Capex Revenue'!C21 | D39: ='GES Capex Revenue'!D21 | E39: ='GES Capex Revenue'!E21 | F39: ='GES Capex Revenue'!F21 | G39: ='GES Capex Revenue'!G21
B41: Basisdefinitionen dieses Blattes: Rohertrag = Gesamtleistung − Materialaufwand; Net Debt (Zeile 29) = Verbindlichkeiten gegenüber Kreditinstituten − Kassenbestand (Stufe 3). Die Definitionen nach Einheit und Datenlage stehen ab Zeile 44; die Folien verwenden die Zeilen 'für Folie'.
B44: Definitionen nach Einheit (Schalter, blau)
B45: Einheit: 1 = Einzelabschluss (Beteiligungsergebnis operativ), 2 = Konzernabschluss | C45: 1 | D45: siehe references/financial-model.md, Abschnitt 3
B47: EBIT Einzelabschluss = Betriebsergebnis + Beteiligungsergebnis − Abschreibungen auf Finanzanlagen | C47: ='GES GuV'!C13+'GES GuV'!C15-'GES GuV'!C16 | D47: ='GES GuV'!D13+'GES GuV'!D15-'GES GuV'!D16 | E47: ='GES GuV'!E13+'GES GuV'!E15-'GES GuV'!E16 | F47: ='GES GuV'!F13+'GES GuV'!F15-'GES GuV'!F16 | G47: ='GES GuV'!G13+'GES GuV'!G15-'GES GuV'!G16
B48: EBITDA Einzelabschluss = EBIT + Abschreibungen + Abschreibungen auf Finanzanlagen | C48: =C47+'GES GuV'!C11+'GES GuV'!C16 | D48: =D47+'GES GuV'!D11+'GES GuV'!D16 | E48: =E47+'GES GuV'!E11+'GES GuV'!E16 | F48: =F47+'GES GuV'!F11+'GES GuV'!F16 | G48: =G47+'GES GuV'!G11+'GES GuV'!G16
B49: EBIT Konzern = Betriebsergebnis | C49: ='GES GuV'!C13 | D49: ='GES GuV'!D13 | E49: ='GES GuV'!E13 | F49: ='GES GuV'!F13 | G49: ='GES GuV'!G13
B50: EBITDA Konzern = EBIT + Abschreibungen | C50: =C49+'GES GuV'!C11 | D50: =D49+'GES GuV'!D11 | E50: =E49+'GES GuV'!E11 | F50: =F49+'GES GuV'!F11 | G50: =G49+'GES GuV'!G11
B51: EBIT für Folie | C51: =IF($C$45=1,C47,C49) | D51: =IF($C$45=1,D47,D49) | E51: =IF($C$45=1,E47,E49) | F51: =IF($C$45=1,F47,F49) | G51: =IF($C$45=1,G47,G49)
...

Sheet GES Capex Revenue
B2: ‹Gesellschaft› – Investitionen, Umsatzerlöse und Absatz 2021–2025
B3: Mio. EUR / Mio. kWh / Mio. m³ | C3: =Cover!$C$24 | D3: =C3+1 | E3: =D3+1 | F3: =E3+1 | G3: =F3+1
B5: Investitionen nach Unternehmensbereichen
B6: Stromversorgung
B7: Gasversorgung
B8: Wasserversorgung
B9: Wärmeversorgung
B10: Telekommunikation
B11: Sonstige Bereiche
B12: Gemeinsame Bereiche
B13: Beteiligungen (Finanzanlagen)
B14: Gesamtinvestitionen | C14: =SUM(C6:C13) | D14: =SUM(D6:D13) | E14: =SUM(E6:E13) | F14: =SUM(F6:F13) | G14: =SUM(G6:G13)
B16: Absatzmengen
B18: Strom (Mio. kWh)
B19: Gas (Mio. kWh)
B20: Wärme / Kälte (Mio. kWh)
B21: Wassernetz (Mio. m³)
B23: Umsatzerlöse nach Unternehmensbereichen
B24: Stromversorgung (inkl. Handelsgeschäfte)
B25: Gasversorgung (inkl. Handelsgeschäfte)
B26: Wärmeversorgung
B27: Betriebsführung Wasserversorgung
B28: Wasserverkauf an ‹Eigenbetrieb›
B29: Konzerninterne Dienstleistungen
B30: Übrige Umsatzerlöse
B31: Umsätze lt. Aufteilung | C31: =SUM(C24:C30) | D31: =SUM(D24:D30) | E31: =SUM(E24:E30) | F31: =SUM(F24:F30) | G31: =SUM(G24:G30)
B32: nachrichtlich: Umsatzerlöse lt. GuV | C32: ='GES GuV'!C5 | D32: ='GES GuV'!D5 | E32: ='GES GuV'!E5 | F32: ='GES GuV'!F5 | G32: ='GES GuV'!G5
B33: Kontrolle: Aufteilung ./. GuV (muss 0 sein; 2025 Rundung) | C33: =ROUND(C31-C32,1) | D33: =ROUND(D31-D32,1) | E33: =ROUND(E31-E32,1) | F33: =ROUND(F31-F32,1) | G33: =ROUND(G31-G32,1)
B35: Umsatzaufteilung in %
B36: Stromversorgung (inkl. Handelsgeschäfte) | C36: =IFERROR(C24/C$31,0) | D36: =IFERROR(D24/D$31,0) | E36: =IFERROR(E24/E$31,0) | F36: =IFERROR(F24/F$31,0) | G36: =IFERROR(G24/G$31,0)
B37: Gasversorgung (inkl. Handelsgeschäfte) | C37: =IFERROR(C25/C$31,0) | D37: =IFERROR(D25/D$31,0) | E37: =IFERROR(E25/E$31,0) | F37: =IFERROR(F25/F$31,0) | G37: =IFERROR(G25/G$31,0)
B38: Wärmeversorgung | C38: =IFERROR(C26/C$31,0) | D38: =IFERROR(D26/D$31,0) | E38: =IFERROR(E26/E$31,0) | F38: =IFERROR(F26/F$31,0) | G38: =IFERROR(G26/G$31,0)
B39: Betriebsführung Wasserversorgung | C39: =IFERROR(C27/C$31,0) | D39: =IFERROR(D27/D$31,0) | E39: =IFERROR(E27/E$31,0) | F39: =IFERROR(F27/F$31,0) | G39: =IFERROR(G27/G$31,0)
B40: Wasserverkauf an ‹Eigenbetrieb› | C40: =IFERROR(C28/C$31,0) | D40: =IFERROR(D28/D$31,0) | E40: =IFERROR(E28/E$31,0) | F40: =IFERROR(F28/F$31,0) | G40: =IFERROR(G28/G$31,0)
B41: Konzerninterne Dienstleistungen | C41: =IFERROR(C29/C$31,0) | D41: =IFERROR(D29/D$31,0) | E41: =IFERROR(E29/E$31,0) | F41: =IFERROR(F29/F$31,0) | G41: =IFERROR(G29/G$31,0)
B42: Übrige Umsatzerlöse | C42: =IFERROR(C30/C$31,0) | D42: =IFERROR(D30/D$31,0) | E42: =IFERROR(E30/E$31,0) | F42: =IFERROR(F30/F$31,0) | G42: =IFERROR(G30/G$31,0)
B43: Summe | C43: =SUM(C36:C42) | D43: =SUM(D36:D42) | E43: =SUM(E36:E42) | F43: =SUM(F36:F42) | G43: =SUM(G36:G42)
B45: Quelle Investitionen: Lagebericht des jeweiligen Jahresabschlusses (JA 2021 S. 5, JA 2022 S. 6, JA 2023 S. 24, JA 2024 S. 25) sowie Geschäftsbericht 2025, Seite 18. Angesetzt ist jeweils die Darstellung des Berichtsjahres selbst. „n.a.“ bedeutet, dass der Bereich im betreffenden Jahr nicht separat ausgewiesen wurde – dies ist nicht mit einem Wert von null gleichzusetzen: 2021 waren die gemeinsamen Bereiche noch auf die Sparten verteilt, die Telekommunikation wurde nur im Jahresabschluss 2024 gesondert gezeigt.
B48: Quelle Umsatzaufteilung: „Aufteilung nach Bereichen“ im Lagebericht (JA 2021 S. 19, JA 2022 S. 20, JA 2023 S. 10, JA 2024 S. 9) sowie Geschäftsbericht 2025, Seite 16. Die Aufteilung 2025 wird nur auf 0,1 Mio. EUR genau veröffentlicht; die Summe der Sparten (473,8) weicht daher um 0,03 Mio. EUR vom GuV-Umsatz (473,770) ab. Quelle Absatzmengen: „Absatzentwicklung“ im jeweiligen Lagebericht bzw. Geschäftsbericht 2025, Seite 15.

Sheet Quellen & Hinweise
B2: ‹Gesellschaft› – Quellen und Hinweise
B3: Gegenstand | C3: Erläuterung
B4: Gesellschaft | C4: ‹Gesellschaft›, ‹Anschrift› – ‹Amtsgericht›, ‹HRB›.
B5: Berichtsumfang | C5: Dargestellt ist ‹der HGB-Einzelabschluss / der Konzernabschluss› der Geschäftsjahre ‹J1› bis ‹J5›. ‹Abgrenzung: Tätigkeitsabschlüsse nach § 6b EnWG nicht enthalten; Konzernabschluss wird nicht aufgestellt (§ 291 HGB) …›
B6: Einheit | C6: Alle Beträge in Mio. EUR (Tausenderwerte des Abschlusses durch 1.000, exakt hinterlegt, auf eine Nachkommastelle angezeigt). Kein Euro-Zeichen in der Mappe.
B7: Quelle GJ ‹J1› | C7: ‹Jahresabschluss zum 31.12.‹J1›, Auszug aus dem Unternehmensregister, Tag der Erstellung …› – liefert GJ ‹J1› (Vorjahresspalte des JA ‹J2›)
B8: Quelle GJ ‹J2› | C8: …
B9: Quelle GJ ‹J3› | C9: …
B10: Quelle GJ ‹J4› | C10: …
B11: Quelle GJ ‹J5› | C11: ‹Geschäftsbericht ‹J5›: Bilanz S. …, GuV S. …, Kapitalflussrechnung S. …, Anhang S. …›
B12: Farbkonvention | C12: Blau = Eingabewert direkt aus dem Abschluss | Schwarz = Formel im Blatt | Grün = Verweis auf ein anderes Blatt | Grau kursiv = im betreffenden Jahr nicht separat ausgewiesen (n.a.)
B13: Definition EBIT / EBITDA | C13: Schalter GES KPIs!C45 = ‹1/2›. ‹Einzelabschluss: EBIT = Betriebliches Ergebnis + Beteiligungsergebnis − Abschreibungen auf Finanzanlagen; EBITDA = EBIT + Abschreibungen (inkl. Finanzanlagen). Konzern: EBIT = Betriebsergebnis; EBITDA = EBIT + Abschreibungen.› Begründung: …
B14: Definition Net Debt | C14: Stufe GES KPIs!C57 = ‹1/2/3›. ‹Definition wortgleich wie in der Fußnote der Folie›. Begründung nach Datenlage: …
... B24: Formatvorlage | C24: Aufbau, Schrift (Univers for Metzler), Farben und Zahlenformate aus dem Financial Model evm/enm bzw. ESWE 2021–2025. Titelbanner weiß auf 003D7C, Kopfzeile weiß auf 3157E3.
